Workbook

Sheet MODE
B2: SET EVENT CODE | C2: 2026cmptx
B3: SET TEAM # | C3: 263

Sheet Data
A1: team_number | B1: total_epa | C1: auto_epa | D1: teleop_epa | E1: endgame_epa
A2: 28 | B2: 25.99 | C2: 8.15 | D2: 12.62 | E2: 5.22 | F2: 24
A3: 263 | B3: 79.71 | C3: 17.33 | D3: 41.46 | E3: 20.92 | F3: 12
A4: 287 | B4: 121.73 | C4: 23.87 | D4: 76.37 | E4: 21.49 | F4: 3
A5: 329 | B5: 29.47 | C5: 3.42 | D5: 16.99 | E5: 9.06 | F5: 25
A6: 353 | B6: 59.82 | C6: 8.83 | D6: 37.18 | E6: 13.81 | F6: 8
A7: 358 | B7: 67.35 | C7: 15.76 | D7: 34.95 | E7: 16.64 | F7: 17
A8: 496 | B8: 46.7 | C8: 6.82 | D8: 26.35 | E8: 13.53 | F8: 18
A9: 514 | B9: 9.13 | C9: 9.17 | D9: 0.81 | E9: -0.85 | F9: 39
A10: 527 | B10: 24.56 | C10: 9.14 | D10: 10.64 | E10: 4.78 | F10: 28
A11: 533 | B11: 22.41 | C11: 9.65 | D11: 6.08 | E11: 6.68 | F11: 21
A12: 545 | B12: 15.22 | C12: 5.44 | D12: 5.85 | E12: 3.92 | F12: 34
A13: 564 | B13: 22.11 | C13: 6.22 | D13: 9.93 | E13: 5.97 | F13: 38
... A49: 11030 | B49: 46.81 | C49: 7.23 | D49: 28.7 | E49: 10.88 | F49: 27

Sheet RANKS
B2: RANKS | C2: TEAM # | D2: TOTAL EPA | E2: AUTO EPA | F2: TELE EPA | G2: END EPA | H2: SHOOTER TYPE | I2: TRENCH
B3: 1 | C3: {=IFERROR(INDEX(Data!A:A, MATCH($B3, Data!$F:$F, 0)), "")} -> 5736 | D3: {=IFERROR(INDEX(Data!B:B, MATCH($B3, Data!$F:$F, 0)), "")} -> 225.59 | E3: {=IFERROR(INDEX(Data!C:C, MATCH($B3, Data!$F:$F, 0)), "")} -> 63.46 | F3: {=IFERROR(INDEX(Data!D:D, MATCH($B3, Data!$F:$F, 0)), "")} -> 116.46 | G3: {=IFERROR(INDEX(Data!E:E, MATCH($B3, Data!$F:$F, 0)), "")} -> 45.66 | H3: =INDIRECT("'"&C3&"'!M12") -> #REF! | I3: =INDIRECT("'"&C3&"'!j12") -> #REF!
B4: 2 | C4: {=IFERROR(INDEX(Data!A:A, MATCH($B4, Data!$F:$F, 0)), "")} -> 870 | D4: {=IFERROR(INDEX(Data!B:B, MATCH($B4, Data!$F:$F, 0)), "")} -> 174.74 | E4: {=IFERROR(INDEX(Data!C:C, MATCH($B4, Data!$F:$F, 0)), "")} -> 46.69 | F4: {=IFERROR(INDEX(Data!D:D, MATCH($B4, Data!$F:$F, 0)), "")} -> 94.46 | G4: {=IFERROR(INDEX(Data!E:E, MATCH($B4, Data!$F:$F, 0)), "")} -> 33.59 | H4: =INDIRECT("'"&C4&"'!M12") -> #REF! | I4: =INDIRECT("'"&C4&"'!j12") -> #REF!
B5: 3 | C5: {=IFERROR(INDEX(Data!A:A, MATCH($B5, Data!$F:$F, 0)), "")} -> 287 | D5: {=IFERROR(INDEX(Data!B:B, MATCH($B5, Data!$F:$F, 0)), "")} -> 121.73 | E5: {=IFERROR(INDEX(Data!C:C, MATCH($B5, Data!$F:$F, 0)), "")} -> 23.87 | F5: {=IFERROR(INDEX(Data!D:D, MATCH($B5, Data!$F:$F, 0)), "")} -> 76.37 | G5: {=IFERROR(INDEX(Data!E:E, MATCH($B5, Data!$F:$F, 0)), "")} -> 21.49 | H5: =INDIRECT("'"&C5&"'!M12") -> #REF! | I5: =INDIRECT("'"&C5&"'!j12") -> #REF!
B6: 4 | C6: {=IFERROR(INDEX(Data!A:A, MATCH($B6, Data!$F:$F, 0)), "")} -> 1880 | D6: {=IFERROR(INDEX(Data!B:B, MATCH($B6, Data!$F:$F, 0)), "")} -> 74.96 | E6: {=IFERROR(INDEX(Data!C:C, MATCH($B6, Data!$F:$F, 0)), "")} -> 11.69 | F6: {=IFERROR(INDEX(Data!D:D, MATCH($B6, Data!$F:$F, 0)), "")} -> 45.83 | G6: {=IFERROR(INDEX(Data!E:E, MATCH($B6, Data!$F:$F, 0)), "")} -> 17.44 | H6: =INDIRECT("'"&C6&"'!M12") -> #REF! | I6: =INDIRECT("'"&C6&"'!j12") -> #REF!
B7: 5 | C7: {=IFERROR(INDEX(Data!A:A, MATCH($B7, Data!$F:$F, 0)), "")} -> 2638 | D7: {=IFERROR(INDEX(Data!B:B, MATCH($B7, Data!$F:$F, 0)), "")} -> 130.91 | E7: {=IFERROR(INDEX(Data!C:C, MATCH($B7, Data!$F:$F, 0)), "")} -> 28.57 | F7: {=IFERROR(INDEX(Data!D:D, MATCH($B7, Data!$F:$F, 0)), "")} -> 75.29 | G7: {=IFERROR(INDEX(Data!E:E, MATCH($B7, Data!$F:$F, 0)), "")} -> 27.06 | H7: =INDIRECT("'"&C7&"'!M12") -> #REF! | I7: =INDIRECT("'"&C7&"'!j12") -> #REF!
B8: 6 | C8: {=IFERROR(INDEX(Data!A:A, MATCH($B8, Data!$F:$F, 0)), "")} -> 810 | D8: {=IFERROR(INDEX(Data!B:B, MATCH($B8, Data!$F:$F, 0)), "")} -> 74.35 | E8: {=IFERROR(INDEX(Data!C:C, MATCH($B8, Data!$F:$F, 0)), "")} -> 19.87 | F8: {=IFERROR(INDEX(Data!D:D, MATCH($B8, Data!$F:$F, 0)), "")} -> 36.47 | G8: {=IFERROR(INDEX(Data!E:E, MATCH($B8, Data!$F:$F, 0)), "")} -> 18.01 | H8: =INDIRECT("'"&C8&"'!M12") -> #REF! | I8: =INDIRECT("'"&C8&"'!j12") -> #REF!
B9: 7 | C9: {=IFERROR(INDEX(Data!A:A, MATCH($B9, Data!$F:$F, 0)), "")} -> 2872 | D9: {=IFERROR(INDEX(Data!B:B, MATCH($B9, Data!$F:$F, 0)), "")} -> 113.91 | E9: {=IFERROR(INDEX(Data!C:C, MATCH($B9, Data!$F:$F, 0)), "")} -> 19.09 | F9: {=IFERROR(INDEX(Data!D:D, MATCH($B9, Data!$F:$F, 0)), "")} -> 70.65 | G9: {=IFERROR(INDEX(Data!E:E, MATCH($B9, Data!$F:$F, 0)), "")} -> 24.17 | H9: =INDIRECT("'"&C9&"'!M12") -> #REF! | I9: =INDIRECT("'"&C9&"'!j12") -> #REF!
B10: 8 | C10: {=IFERROR(INDEX(Data!A:A, MATCH($B10, Data!$F:$F, 0)), "")} -> 353 | D10: {=IFERROR(INDEX(Data!B:B, MATCH($B10, Data!$F:$F, 0)), "")} -> 59.82 | E10: {=IFERROR(INDEX(Data!C:C, MATCH($B10, Data!$F:$F, 0)), "")} -> 8.83 | F10: {=IFERROR(INDEX(Data!D:D, MATCH($B10, Data!$F:$F, 0)), "")} -> 37.18 | G10: {=IFERROR(INDEX(Data!E:E, MATCH($B10, Data!$F:$F, 0)), "")} -> 13.81 | H10: =INDIRECT("'"&C10&"'!M12") -> #REF! | I10: =INDIRECT("'"&C10&"'!j12") -> #REF!
B11: 9 | C11: {=IFERROR(INDEX(Data!A:A, MATCH($B11, Data!$F:$F, 0)), "")} -> 1554 | D11: {=IFERROR(INDEX(Data!B:B, MATCH($B11, Data!$F:$F, 0)), "")} -> 44.18 | E11: {=IFERROR(INDEX(Data!C:C, MATCH($B11, Data!$F:$F, 0)), "")} -> 11.06 | F11: {=IFERROR(INDEX(Data!D:D, MATCH($B11, Data!$F:$F, 0)), "")} -> 31.23 | G11: {=IFERROR(INDEX(Data!E:E, MATCH($B11, Data!$F:$F, 0)), "")} -> 1.89 | H11: =INDIRECT("'"&C11&"'!M12") -> #REF! | I11: =INDIRECT("'"&C11&"'!j12") -> #REF!
B12: 10 | C12: {=IFERROR(INDEX(Data!A:A, MATCH($B12, Data!$F:$F, 0)), "")} -> 4458 | D12: {=IFERROR(INDEX(Data!B:B, MATCH($B12, Data!$F:$F, 0)), "")} -> 43.67 | E12: {=IFERROR(INDEX(Data!C:C, MATCH($B12, Data!$F:$F, 0)), "")} -> 9.36 | F12: {=IFERROR(INDEX(Data!D:D, MATCH($B12, Data!$F:$F, 0)), "")} -> 19.57 | G12: {=IFERROR(INDEX(Data!E:E, MATCH($B12, Data!$F:$F, 0)), "")} -> 14.73 | H12: =INDIRECT("'"&C12&"'!M12") -> #REF! | I12: =INDIRECT("'"&C12&"'!j12") -> #REF!
B13: 11 | C13: {=IFERROR(INDEX(Data!A:A, MATCH($B13, Data!$F:$F, 0)), "")} -> 1468 | D13: {=IFERROR(INDEX(Data!B:B, MATCH($B13, Data!$F:$F, 0)), "")} -> 43.6 | E13: {=IFERROR(INDEX(Data!C:C, MATCH($B13, Data!$F:$F, 0)), "")} -> 10.57 | F13: {=IFERROR(INDEX(Data!D:D, MATCH($B13, Data!$F:$F, 0)), "")} -> 23.09 | G13: {=IFERROR(INDEX(Data!E:E, MATCH($B13, Data!$F:$F, 0)), "")} -> 9.94 | H13: =INDIRECT("'"&C13&"'!M12") -> #REF! | I13: =INDIRECT("'"&C13&"'!j12") -> #REF!
B14: 12 | C14: {=IFERROR(INDEX(Data!A:A, MATCH($B14, Data!$F:$F, 0)), "")} -> 263 | D14: {=IFERROR(INDEX(Data!B:B, MATCH($B14, Data!$F:$F, 0)), "")} -> 79.71 | E14: {=IFERROR(INDEX(Data!C:C, MATCH($B14, Data!$F:$F, 0)), "")} -> 17.33 | F14: {=IFERROR(INDEX(Data!D:D, MATCH($B14, Data!$F:$F, 0)), "")} -> 41.46 | G14: {=IFERROR(INDEX(Data!E:E, MATCH($B14, Data!$F:$F, 0)), "")} -> 20.92 | H14: =INDIRECT("'"&C14&"'!M12") | I14: =INDIRECT("'"&C14&"'!j12")
... B61: 59 | C61: {=IFERROR(INDEX(Data!A:A, MATCH($B61, Data!$F:$F, 0)), "")} | D61: {=IFERROR(INDEX(Data!B:B, MATCH($B61, Data!$F:$F, 0)), "")} | E61: {=IFERROR(INDEX(Data!C:C, MATCH($B61, Data!$F:$F, 0)), "")} | F61: {=IFERROR(INDEX(Data!D:D, MATCH($B61, Data!$F:$F, 0)), "")} | G61: {=IFERROR(INDEX(Data!E:E, MATCH($B61, Data!$F:$F, 0)), "")} | H61: =INDIRECT("'"&C61&"'!M12") | I61: =INDIRECT("'"&C61&"'!j12")
B62: 60 | C62: {=IFERROR(INDEX(Data!A:A, MATCH($B62, Data!$F:$F, 0)), "")} | D62: {=IFERROR(INDEX(Data!F:F, MATCH($B62, Data!$M:$M, 0)), "")} | E62: {=IFERROR(INDEX(Data!G:G, MATCH($B62, Data!$M:$M, 0)), "")} | F62: {=IFERROR(INDEX(Data!H:H, MATCH($B62, Data!$M:$M, 0)), "")} | G62: {=IFERROR(INDEX(Data!I:I, MATCH($B62, Data!$M:$M, 0)), "")} | H62: =INDIRECT("'"&C62&"'!M12") | I62: =INDIRECT("'"&C62&"'!j12")

Sheet RANK BY EPA
B2: P-RANK | C2: RANKS | D2: TEAM # | E2: TOTAL EPA | F2: AUTO EPA | G2: TELE EPA | H2: END EPA | I2: SHOOTER TYPE | J2: TRENCH
A3: 1 | B3: 1 | C3: {=IFERROR(INDEX(Data!F:F, MATCH($E3, Data!$B:$B, 0)), "")} -> 1 | D3: {=IFERROR(INDEX(Data!A:A, MATCH($E3, Data!$B:$B, 0)), "")} -> 5736 | E3: =LARGE(Data!$B$2:$B1000,A3 ) -> 225.59 | F3: {=IFERROR(INDEX(Data!C:C, MATCH($E3, Data!$B:$B, 0)), "")} -> 63.46 | G3: {=IFERROR(INDEX(Data!D:D, MATCH($E3, Data!$B:$B, 0)), "")} -> 116.46 | H3: {=IFERROR(INDEX(Data!E:E, MATCH($E3, Data!$B:$B, 0)), "")} -> 45.66 | I3: =INDIRECT("'"&D3&"'!M12") -> #REF! | J3: =INDIRECT("'"&D3&"'!j12") -> #REF!
A4: 2 | B4: 2 | C4: {=IFERROR(INDEX(Data!F:F, MATCH($E4, Data!$B:$B, 0)), "")} -> 2 | D4: {=IFERROR(INDEX(Data!A:A, MATCH($E4, Data!$B:$B, 0)), "")} -> 870 | E4: =LARGE(Data!$B$2:$B1000,A4 ) -> 174.74 | F4: {=IFERROR(INDEX(Data!C:C, MATCH($E4, Data!$B:$B, 0)), "")} -> 46.69 | G4: {=IFERROR(INDEX(Data!D:D, MATCH($E4, Data!$B:$B, 0)), "")} -> 94.46 | H4: {=IFERROR(INDEX(Data!E:E, MATCH($E4, Data!$B:$B, 0)), "")} -> 33.59 | I4: =INDIRECT("'"&D4&"'!M12") -> #REF! | J4: =INDIRECT("'"&D4&"'!j12") -> #REF!
A5: 3 | B5: 3 | C5: {=IFERROR(INDEX(Data!F:F, MATCH($E5, Data!$B:$B, 0)), "")} -> 5 | D5: {=IFERROR(INDEX(Data!A:A, MATCH($E5, Data!$B:$B, 0)), "")} -> 2638 | E5: =LARGE(Data!$B$2:$B1000,A5 ) -> 130.91 | F5: {=IFERROR(INDEX(Data!C:C, MATCH($E5, Data!$B:$B, 0)), "")} -> 28.57 | G5: {=IFERROR(INDEX(Data!D:D, MATCH($E5, Data!$B:$B, 0)), "")} -> 75.29 | H5: {=IFERROR(INDEX(Data!E:E, MATCH($E5, Data!$B:$B, 0)), "")} -> 27.06 | I5: =INDIRECT("'"&D5&"'!M12") -> #REF! | J5: =INDIRECT("'"&D5&"'!j12") -> #REF!
A6: 4 | B6: 4 | C6: {=IFERROR(INDEX(Data!F:F, MATCH($E6, Data!$B:$B, 0)), "")} -> 15 | D6: {=IFERROR(INDEX(Data!A:A, MATCH($E6, Data!$B:$B, 0)), "")} -> 8267 | E6: =LARGE(Data!$B$2:$B1000,A6 ) -> 124.23 | F6: {=IFERROR(INDEX(Data!C:C, MATCH($E6, Data!$B:$B, 0)), "")} -> 28.83 | G6: {=IFERROR(INDEX(Data!D:D, MATCH($E6, Data!$B:$B, 0)), "")} -> 67.1 | H6: {=IFERROR(INDEX(Data!E:E, MATCH($E6, Data!$B:$B, 0)), "")} -> 28.3 | I6: =INDIRECT("'"&D6&"'!M12") -> #REF! | J6: =INDIRECT("'"&D6&"'!j12") -> #REF!
A7: 5 | B7: 5 | C7: {=IFERROR(INDEX(Data!F:F, MATCH($E7, Data!$B:$B, 0)), "")} -> 3 | D7: {=IFERROR(INDEX(Data!A:A, MATCH($E7, Data!$B:$B, 0)), "")} -> 287 | E7: =LARGE(Data!$B$2:$B1000,A7 ) -> 121.73 | F7: {=IFERROR(INDEX(Data!C:C, MATCH($E7, Data!$B:$B, 0)), "")} -> 23.87 | G7: {=IFERROR(INDEX(Data!D:D, MATCH($E7, Data!$B:$B, 0)), "")} -> 76.37 | H7: {=IFERROR(INDEX(Data!E:E, MATCH($E7, Data!$B:$B, 0)), "")} -> 21.49 | I7: =INDIRECT("'"&D7&"'!M12") -> #REF! | J7: =INDIRECT("'"&D7&"'!j12") -> #REF!
A8: 6 | B8: 6 | C8: {=IFERROR(INDEX(Data!F:F, MATCH($E8, Data!$B:$B, 0)), "")} -> 7 | D8: {=IFERROR(INDEX(Data!A:A, MATCH($E8, Data!$B:$B, 0)), "")} -> 2872 | E8: =LARGE(Data!$B$2:$B1000,A8 ) -> 113.91 | F8: {=IFERROR(INDEX(Data!C:C, MATCH($E8, Data!$B:$B, 0)), "")} -> 19.09 | G8: {=IFERROR(INDEX(Data!D:D, MATCH($E8, Data!$B:$B, 0)), "")} -> 70.65 | H8: {=IFERROR(INDEX(Data!E:E, MATCH($E8, Data!$B:$B, 0)), "")} -> 24.17 | I8: =INDIRECT("'"&D8&"'!M12") -> #REF! | J8: =INDIRECT("'"&D8&"'!j12") -> #REF!
A9: 7 | B9: 7 | C9: {=IFERROR(INDEX(Data!F:F, MATCH($E9, Data!$B:$B, 0)), "")} -> 12 | D9: {=IFERROR(INDEX(Data!A:A, MATCH($E9, Data!$B:$B, 0)), "")} -> 263 | E9: =LARGE(Data!$B$2:$B1000,A9 ) -> 79.71 | F9: {=IFERROR(INDEX(Data!C:C, MATCH($E9, Data!$B:$B, 0)), "")} -> 17.33 | G9: {=IFERROR(INDEX(Data!D:D, MATCH($E9, Data!$B:$B, 0)), "")} -> 41.46 | H9: {=IFERROR(INDEX(Data!E:E, MATCH($E9, Data!$B:$B, 0)), "")} -> 20.92 | I9: =INDIRECT("'"&D9&"'!M12") | J9: =INDIRECT("'"&D9&"'!j12")
A10: 8 | B10: 8 | C10: {=IFERROR(INDEX(Data!F:F, MATCH($E10, Data!$B:$B, 0)), "")} -> 16 | D10: {=IFERROR(INDEX(Data!A:A, MATCH($E10, Data!$B:$B, 0)), "")} -> 3950 | E10: =LARGE(Data!$B$2:$B1000,A10 ) -> 77.52 | F10: {=IFERROR(INDEX(Data!C:C, MATCH($E10, Data!$B:$B, 0)), "")} -> 21.16 | G10: {=IFERROR(INDEX(Data!D:D, MATCH($E10, Data!$B:$B, 0)), "")} -> 42.31 | H10: {=IFERROR(INDEX(Data!E:E, MATCH($E10, Data!$B:$B, 0)), "")} -> 14.06 | I10: =INDIRECT("'"&D10&"'!M12") -> #REF! | J10: =INDIRECT("'"&D10&"'!j12") -> #REF!
A11: 9 | B11: 9 | C11: {=IFERROR(INDEX(Data!F:F, MATCH($E11, Data!$B:$B, 0)), "")} -> 4 | D11: {=IFERROR(INDEX(Data!A:A, MATCH($E11, Data!$B:$B, 0)), "")} -> 1880 | E11: =LARGE(Data!$B$2:$B1000,A11 ) -> 74.96 | F11: {=IFERROR(INDEX(Data!C:C, MATCH($E11, Data!$B:$B, 0)), "")} -> 11.69 | G11: {=IFERROR(INDEX(Data!D:D, MATCH($E11, Data!$B:$B, 0)), "")} -> 45.83 | H11: {=IFERROR(INDEX(Data!E:E, MATCH($E11, Data!$B:$B, 0)), "")} -> 17.44 | I11: =INDIRECT("'"&D11&"'!M12") -> #REF! | J11: =INDIRECT("'"&D11&"'!j12") -> #REF!
A12: 10 | B12: 10 | C12: {=IFERROR(INDEX(Data!F:F, MATCH($E12, Data!$B:$B, 0)), "")} -> 6 | D12: {=IFERROR(INDEX(Data!A:A, MATCH($E12, Data!$B:$B, 0)), "")} -> 810 | E12: =LARGE(Data!$B$2:$B1000,A12 ) -> 74.35 | F12: {=IFERROR(INDEX(Data!C:C, MATCH($E12, Data!$B:$B, 0)), "")} -> 19.87 | G12: {=IFERROR(INDEX(Data!D:D, MATCH($E12, Data!$B:$B, 0)), "")} -> 36.47 | H12: {=IFERROR(INDEX(Data!E:E, MATCH($E12, Data!$B:$B, 0)), "")} -> 18.01 | I12: =INDIRECT("'"&D12&"'!M12") -> #REF! | J12: =INDIRECT("'"&D12&"'!j12") -> #REF!
A13: 11 | B13: 11 | C13: {=IFERROR(INDEX(Data!F:F, MATCH($E13, Data!$B:$B, 0)), "")} -> 17 | D13: {=IFERROR(INDEX(Data!A:A, MATCH($E13, Data!$B:$B, 0)), "")} -> 358 | E13: =LARGE(Data!$B$2:$B1000,A13 ) -> 67.35 | F13: {=IFERROR(INDEX(Data!C:C, MATCH($E13, Data!$B:$B, 0)), "")} -> 15.76 | G13: {=IFERROR(INDEX(Data!D:D, MATCH($E13, Data!$B:$B, 0)), "")} -> 34.95 | H13: {=IFERROR(INDEX(Data!E:E, MATCH($E13, Data!$B:$B, 0)), "")} -> 16.64 | I13: =INDIRECT("'"&D13&"'!M12") -> #REF! | J13: =INDIRECT("'"&D13&"'!j12") -> #REF!
A14: 12 | B14: 12 | C14: {=IFERROR(INDEX(Data!F:F, MATCH($E14, Data!$B:$B, 0)), "")} -> 8 | D14: {=IFERROR(INDEX(Data!A:A, MATCH($E14, Data!$B:$B, 0)), "")} -> 353 | E14: =LARGE(Data!$B$2:$B1000,A14 ) -> 59.82 | F14: {=IFERROR(INDEX(Data!C:C, MATCH($E14, Data!$B:$B, 0)), "")} -> 8.83 | G14: {=IFERROR(INDEX(Data!D:D, MATCH($E14, Data!$B:$B, 0)), "")} -> 37.18 | H14: {=IFERROR(INDEX(Data!E:E, MATCH($E14, Data!$B:$B, 0)), "")} -> 13.81 | I14: =INDIRECT("'"&D14&"'!M12") -> #REF! | J14: =INDIRECT("'"&D14&"'!j12") -> #REF!
A15: 13 | B15: 13 | C15: {=IFERROR(INDEX(Data!F:F, MATCH($E15, Data!$B:$B, 0)), "")} -> 13 | D15: {=IFERROR(INDEX(Data!A:A, MATCH($E15, Data!$B:$B, 0)), "")} -> 6423 | E15: =LARGE(Data!$B$2:$B1000,A15 ) -> 50.75 | F15: {=IFERROR(INDEX(Data!C:C, MATCH($E15, Data!$B:$B, 0)), "")} -> 5.28 | G15: {=IFERROR(INDEX(Data!D:D, MATCH($E15, Data!$B:$B, 0)), "")} -> 30.25 | H15: {=IFERROR(INDEX(Data!E:E, MATCH($E15, Data!$B:$B, 0)), "")} -> 15.22 | I15: =INDIRECT("'"&D15&"'!M12") -> #REF! | J15: =INDIRECT("'"&D15&"'!j12") -> #REF!
A16: 14 | B16: 14 | C16: {=IFERROR(INDEX(Data!F:F, MATCH($E16, Data!$B:$B, 0)), "")} -> 29 | D16: {=IFERROR(INDEX(Data!A:A, MATCH($E16, Data!$B:$B, 0)), "")} -> 2875 | E16: =LARGE(Data!$B$2:$B1000,A16 ) -> 48.38 | F16: {=IFERROR(INDEX(Data!C:C, MATCH($E16, Data!$B:$B, 0)), "")} -> 11.41 | G16: {=IFERROR(INDEX(Data!D:D, MATCH($E16, Data!$B:$B, 0)), "")} -> 24.35 | H16: {=IFERROR(INDEX(Data!E:E, MATCH($E16, Data!$B:$B, 0)), "")} -> 12.61 | I16: =INDIRECT("'"&D16&"'!M12") -> #REF! | J16: =INDIRECT("'"&D16&"'!j12") -> #REF!
A17: 15 | B17: 15 | C17: {=IFERROR(INDEX(Data!F:F, MATCH($E17, Data!$B:$B, 0)), "")} -> 27 | D17: {=IFERROR(INDEX(Data!A:A, MATCH($E17, Data!$B:$B, 0)), "")} -> 11030 | E17: =LARGE(Data!$B$2:$B1000,A17 ) -> 46.81 | F17: {=IFERROR(INDEX(Data!C:C, MATCH($E17, Data!$B:$B, 0)), "")} -> 7.23 | G17: {=IFERROR(INDEX(Data!D:D, MATCH($E17, Data!$B:$B, 0)), "")} -> 28.7 | H17: {=IFERROR(INDEX(Data!E:E, MATCH($E17, Data!$B:$B, 0)), "")} -> 10.88 | I17: =INDIRECT("'"&D17&"'!M12") -> #REF! | J17: =INDIRECT("'"&D17&"'!j12") -> #REF!
A18: 16 | B18: 16 | C18: {=IFERROR(INDEX(Data!F:F, MATCH($E18, Data!$B:$B, 0)), "")} -> 18 | D18: {=IFERROR(INDEX(Data!A:A, MATCH($E18, Data!$B:$B, 0)), "")} -> 496 | E18: =LARGE(Data!$B$2:$B1000,A18 ) -> 46.7 | F18: {=IFERROR(INDEX(Data!C:C, MATCH($E18, Data!$B:$B, 0)), "")} -> 6.82 | G18: {=IFERROR(INDEX(Data!D:D, MATCH($E18, Data!$B:$B, 0)), "")} -> 26.35 | H18: {=IFERROR(INDEX(Data!E:E, MATCH($E18, Data!$B:$B, 0)), "")} -> 13.53 | I18: =INDIRECT("'"&D18&"'!M12") -> #REF! | J18: =INDIRECT("'"&D18&"'!j12") -> #REF!
A19: 17 | B19: 17 | C19: {=IFERROR(INDEX(Data!F:F, MATCH($E19, Data!$B:$B, 0)), "")} -> 9 | D19: {=IFERROR(INDEX(Data!A:A, MATCH($E19, Data!$B:$B, 0)), "")} -> 1554 | E19: =LARGE(Data!$B$2:$B1000,A19 ) -> 44.18 | F19: {=IFERROR(INDEX(Data!C:C, MATCH($E19, Data!$B:$B, 0)), "")} -> 11.06 | G19: {=IFERROR(INDEX(Data!D:D, MATCH($E19, Data!$B:$B, 0)), "")} -> 31.23 | H19: {=IFERROR(INDEX(Data!E:E, MATCH($E19, Data!$B:$B, 0)), "")} -> 1.89 | I19: =INDIRECT("'"&D19&"'!M12") -> #REF! | J19: =INDIRECT("'"&D19&"'!j12") -> #REF!
A20: 18 | B20: 18 | C20: {=IFERROR(INDEX(Data!F:F, MATCH($E20, Data!$B:$B, 0)), "")} -> 10 | D20: {=IFERROR(INDEX(Data!A:A, MATCH($E20, Data!$B:$B, 0)), "")} -> 4458 | E20: =LARGE(Data!$B$2:$B1000,A20 ) -> 43.67 | F20: {=IFERROR(INDEX(Data!C:C, MATCH($E20, Data!$B:$B, 0)), "")} -> 9.36 | G20: {=IFERROR(INDEX(Data!D:D, MATCH($E20, Data!$B:$B, 0)), "")} -> 19.57 | H20: {=IFERROR(INDEX(Data!E:E, MATCH($E20, Data!$B:$B, 0)), "")} -> 14.73 | I20: =INDIRECT("'"&D20&"'!M12") -> #REF! | J20: =INDIRECT("'"&D20&"'!j12") -> #REF!
A21: 19 | B21: 19 | C21: {=IFERROR(INDEX(Data!F:F, MATCH($E21, Data!$B:$B, 0)), "")} -> 11 | D21: {=IFERROR(INDEX(Data!A:A, MATCH($E21, Data!$B:$B, 0)), "")} -> 1468 | E21: =LARGE(Data!$B$2:$B1000,A21 ) -> 43.6 | F21: {=IFERROR(INDEX(Data!C:C, MATCH($E21, Data!$B:$B, 0)), "")} -> 10.57 | G21: {=IFERROR(INDEX(Data!D:D, MATCH($E21, Data!$B:$B, 0)), "")} -> 23.09 | H21: {=IFERROR(INDEX(Data!E:E, MATCH($E21, Data!$B:$B, 0)), "")} -> 9.94 | I21: =INDIRECT("'"&D21&"'!M12") -> #REF! | J21: =INDIRECT("'"&D21&"'!j12") -> #REF!
A22: 20 | B22: 20 | C22: {=IFERROR(INDEX(Data!F:F, MATCH($E22, Data!$B:$B, 0)), "")} -> 36 | D22: {=IFERROR(INDEX(Data!A:A, MATCH($E22, Data!$B:$B, 0)), "")} -> 2869 | E22: =LARGE(Data!$B$2:$B1000,A22 ) -> 41.7 | F22: {=IFERROR(INDEX(Data!C:C, MATCH($E22, Data!$B:$B, 0)), "")} -> 10.96 | G22: {=IFERROR(INDEX(Data!D:D, MATCH($E22, Data!$B:$B, 0)), "")} -> 25.49 | H22: {=IFERROR(INDEX(Data!E:E, MATCH($E22, Data!$B:$B, 0)), "")} -> 5.24 | I22: =INDIRECT("'"&D22&"'!M12") -> #REF! | J22: =INDIRECT("'"&D22&"'!j12") -> #REF!
A23: 21 | B23: 21 | C23: {=IFERROR(INDEX(Data!F:F, MATCH($E23, Data!$B:$B, 0)), "")} -> 35 | D23: {=IFERROR(INDEX(Data!A:A, MATCH($E23, Data!$B:$B, 0)), "")} -> 9016 | E23: =LARGE(Data!$B$2:$B1000,A23 ) -> 39.71 | F23: {=IFERROR(INDEX(Data!C:C, MATCH($E23, Data!$B:$B, 0)), "")} -> 13.26 | G23: {=IFERROR(INDEX(Data!D:D, MATCH($E23, Data!$B:$B, 0)), "")} -> 15.76 | H23: {=IFERROR(INDEX(Data!E:E, MATCH($E23, Data!$B:$B, 0)), "")} -> 10.7 | I23: =INDIRECT("'"&D23&"'!M12") -> #REF! | J23: =INDIRECT("'"&D23&"'!j12") -> #REF!
A24: 22 | B24: 22 | C24: {=IFERROR(INDEX(Data!F:F, MATCH($E24, Data!$B:$B, 0)), "")} -> 32 | D24: {=IFERROR(INDEX(Data!A:A, MATCH($E24, Data!$B:$B, 0)), "")} -> 871 | E24: =LARGE(Data!$B$2:$B1000,A24 ) -> 38.67 | F24: {=IFERROR(INDEX(Data!C:C, MATCH($E24, Data!$B:$B, 0)), "")} -> 13.07 | G24: {=IFERROR(INDEX(Data!D:D, MATCH($E24, Data!$B:$B, 0)), "")} -> 18.13 | H24: {=IFERROR(INDEX(Data!E:E, MATCH($E24, Data!$B:$B, 0)), "")} -> 7.46 | I24: =INDIRECT("'"&D24&"'!M12") -> #REF! | J24: =INDIRECT("'"&D24&"'!j12") -> #REF!
A25: 23 | B25: 23 | C25: {=IFERROR(INDEX(Data!F:F, MATCH($E25, Data!$B:$B, 0)), "")} -> 22 | D25: {=IFERROR(INDEX(Data!A:A, MATCH($E25, Data!$B:$B, 0)), "")} -> 9646 | E25: =LARGE(Data!$B$2:$B1000,A25 ) -> 38.43 | F25: {=IFERROR(INDEX(Data!C:C, MATCH($E25, Data!$B:$B, 0)), "")} -> 7.46 | G25: {=IFERROR(INDEX(Data!D:D, MATCH($E25, Data!$B:$B, 0)), "")} -> 23 | H25: {=IFERROR(INDEX(Data!E:E, MATCH($E25, Data!$B:$B, 0)), "")} -> 7.98 | I25: =INDIRECT("'"&D25&"'!M12") -> #REF! | J25: =INDIRECT("'"&D25&"'!j12") -> #REF!
A26: 24 | B26: 24 | C26: {=IFERROR(INDEX(Data!F:F, MATCH($E26, Data!$B:$B, 0)), "")} -> 46 | D26: {=IFERROR(INDEX(Data!A:A, MATCH($E26, Data!$B:$B, 0)), "")} -> 5016 | E26: =LARGE(Data!$B$2:$B1000,A26 ) -> 37.67 | F26: {=IFERROR(INDEX(Data!C:C, MATCH($E26, Data!$B:$B, 0)), "")} -> 5.71 | G26: {=IFERROR(INDEX(Data!D:D, MATCH($E26, Data!$B:$B, 0)), "")} -> 20.44 | H26: {=IFERROR(INDEX(Data!E:E, MATCH($E26, Data!$B:$B, 0)), "")} -> 11.52 | I26: =INDIRECT("'"&D26&"'!M12") -> #REF! | J26: =INDIRECT("'"&D26&"'!j12") -> #REF!
A27: 25 | B27: 25 | C27: {=IFERROR(INDEX(Data!F:F, MATCH($E27, Data!$B:$B, 0)), "")} -> 31 | D27: {=IFERROR(INDEX(Data!A:A, MATCH($E27, Data!$B:$B, 0)), "")} -> 6806 | E27: =LARGE(Data!$B$2:$B1000,A27 ) -> 36.75 | F27: {=IFERROR(INDEX(Data!C:C, MATCH($E27, Data!$B:$B, 0)), "")} -> 6.63 | G27: {=IFERROR(INDEX(Data!D:D, MATCH($E27, Data!$B:$B, 0)), "")} -> 21.63 | H27: {=IFERROR(INDEX(Data!E:E, MATCH($E27, Data!$B:$B, 0)), "")} -> 8.5 | I27: =INDIRECT("'"&D27&"'!M12") -> #REF! | J27: =INDIRECT("'"&D27&"'!j12") -> #REF!
A28: 26 | B28: 26 | C28: {=IFERROR(INDEX(Data!F:F, MATCH($E28, Data!$B:$B, 0)), "")} -> 14 | D28: {=IFERROR(INDEX(Data!A:A, MATCH($E28, Data!$B:$B, 0)), "")} -> 1546 | E28: =LARGE(Data!$B$2:$B1000,A28 ) -> 33.62 | F28: {=IFERROR(INDEX(Data!C:C, MATCH($E28, Data!$B:$B, 0)), "")} -> 9.41 | G28: {=IFERROR(INDEX(Data!D:D, MATCH($E28, Data!$B:$B, 0)), "")} -> 17.42 | H28: {=IFERROR(INDEX(Data!E:E, MATCH($E28, Data!$B:$B, 0)), "")} -> 6.78 | I28: =INDIRECT("'"&D28&"'!M12") -> #REF! | J28: =INDIRECT("'"&D28&"'!j12") -> #REF!
A29: 27 | B29: 27 | C29: {=IFERROR(INDEX(Data!F:F, MATCH($E29, Data!$B:$B, 0)), "")} -> 25 | D29: {=IFERROR(INDEX(Data!A:A, MATCH($E29, Data!$B:$B, 0)), "")} -> 329 | E29: =LARGE(Data!$B$2:$B1000,A29 ) -> 29.47 | F29: {=IFERROR(INDEX(Data!C:C, MATCH($E29, Data!$B:$B, 0)), "")} -> 3.42 | G29: {=IFERROR(INDEX(Data!D:D, MATCH($E29, Data!$B:$B, 0)), "")} -> 16.99 | H29: {=IFERROR(INDEX(Data!E:E, MATCH($E29, Data!$B:$B, 0)), "")} -> 9.06 | I29: =INDIRECT("'"&D29&"'!M12") -> #REF! | J29: =INDIRECT("'"&D29&"'!j12") -> #REF!
A30: 28 | B30: 28 | C30: {=IFERROR(INDEX(Data!F:F, MATCH($E30, Data!$B:$B, 0)), "")} -> 19 | D30: {=IFERROR(INDEX(Data!A:A, MATCH($E30, Data!$B:$B, 0)), "")} -> 1803 | E30: =LARGE(Data!$B$2:$B1000,A30 ) -> 27.5 | F30: {=IFERROR(INDEX(Data!C:C, MATCH($E30, Data!$B:$B, 0)), "")} -> 7.49 | G30: {=IFERROR(INDEX(Data!D:D, MATCH($E30, Data!$B:$B, 0)), "")} -> 14.61 | H30: {=IFERROR(INDEX(Data!E:E, MATCH($E30, Data!$B:$B, 0)), "")} -> 5.39 | I30: =INDIRECT("'"&D30&"'!M12") -> #REF! | J30: =INDIRECT("'"&D30&"'!j12") -> #REF!
A31: 29 | B31: 29 | C31: {=IFERROR(INDEX(Data!F:F, MATCH($E31, Data!$B:$B, 0)), "")} -> 24 | D31: {=IFERROR(INDEX(Data!A:A, MATCH($E31, Data!$B:$B, 0)), "")} -> 28 | E31: =LARGE(Data!$B$2:$B1000,A31 ) -> 25.99 | F31: {=IFERROR(INDEX(Data!C:C, MATCH($E31, Data!$B:$B, 0)), "")} -> 8.15 | G31: {=IFERROR(INDEX(Data!D:D, MATCH($E31, Data!$B:$B, 0)), "")} -> 12.62 | H31: {=IFERROR(INDEX(Data!E:E, MATCH($E31, Data!$B:$B, 0)), "")} -> 5.22 | I31: =INDIRECT("'"&D31&"'!M12") -> #REF! | J31: =INDIRECT("'"&D31&"'!j12") -> #REF!
A32: 30 | B32: 30 | C32: {=IFERROR(INDEX(Data!F:F, MATCH($E32, Data!$B:$B, 0)), "")} -> 44 | D32: {=IFERROR(INDEX(Data!A:A, MATCH($E32, Data!$B:$B, 0)), "")} -> 3624 | E32: =LARGE(Data!$B$2:$B1000,A32 ) -> 24.96 | F32: {=IFERROR(INDEX(Data!C:C, MATCH($E32, Data!$B:$B, 0)), "")} -> 6.29 | G32: {=IFERROR(INDEX(Data!D:D, MATCH($E32, Data!$B:$B, 0)), "")} -> 15.46 | H32: {=IFERROR(INDEX(Data!E:E, MATCH($E32, Data!$B:$B, 0)), "")} -> 3.21 | I32: =INDIRECT("'"&D32&"'!M12") -> #REF! | J32: =INDIRECT("'"&D32&"'!j12") -> #REF!
A33: 31 | B33: 31 | C33: {=IFERROR(INDEX(Data!F:F, MATCH($E33, Data!$B:$B, 0)), "")} -> 28 | D33: {=IFERROR(INDEX(Data!A:A, MATCH($E33, Data!$B:$B, 0)), "")} -> 527 | E33: =LARGE(Data!$B$2:$B1000,A33 ) -> 24.56 | F33: {=IFERROR(INDEX(Data!C:C, MATCH($E33, Data!$B:$B, 0)), "")} -> 9.14 | G33: {=IFERROR(INDEX(Data!D:D, MATCH($E33, Data!$B:$B, 0)), "")} -> 10.64 | H33: {=IFERROR(INDEX(Data!E:E, MATCH($E33, Data!$B:$B, 0)), "")} -> 4.78 | I33: =INDIRECT("'"&D33&"'!M12") -> #REF! | J33: =INDIRECT("'"&D33&"'!j12") -> #REF!
A34: 32 | B34: 32 | C34: {=IFERROR(INDEX(Data!F:F, MATCH($E34, Data!$B:$B, 0)), "")} -> 42 | D34: {=IFERROR(INDEX(Data!A:A, MATCH($E34, Data!$B:$B, 0)), "")} -> 3137 | E34: =LARGE(Data!$B$2:$B1000,A34 ) -> 23.54 | F34: {=IFERROR(INDEX(Data!C:C, MATCH($E34, Data!$B:$B, 0)), "")} -> 9.55 | G34: {=IFERROR(INDEX(Data!D:D, MATCH($E34, Data!$B:$B, 0)), "")} -> 6.95 | H34: {=IFERROR(INDEX(Data!E:E, MATCH($E34, Data!$B:$B, 0)), "")} -> 7.05 | I34: =INDIRECT("'"&D34&"'!M12") -> #REF! | J34: =INDIRECT("'"&D34&"'!j12") -> #REF!
A35: 33 | B35: 33 | C35: {=IFERROR(INDEX(Data!F:F, MATCH($E35, Data!$B:$B, 0)), "")} -> 48 | D35: {=IFERROR(INDEX(Data!A:A, MATCH($E35, Data!$B:$B, 0)), "")} -> 3171 | E35: =LARGE(Data!$B$2:$B1000,A35 ) -> 23.49 | F35: {=IFERROR(INDEX(Data!C:C, MATCH($E35, Data!$B:$B, 0)), "")} -> 5.7 | G35: {=IFERROR(INDEX(Data!D:D, MATCH($E35, Data!$B:$B, 0)), "")} -> 6.86 | H35: {=IFERROR(INDEX(Data!E:E, MATCH($E35, Data!$B:$B, 0)), "")} -> 10.92 | I35: =INDIRECT("'"&D35&"'!M12") -> #REF! | J35: =INDIRECT("'"&D35&"'!j12") -> #REF!
A36: 34 | B36: 34 | C36: {=IFERROR(INDEX(Data!F:F, MATCH($E36, Data!$B:$B, 0)), "")} -> 23 | D36: {=IFERROR(INDEX(Data!A:A, MATCH($E36, Data!$B:$B, 0)), "")} -> 2161 | E36: =LARGE(Data!$B$2:$B1000,A36 ) -> 22.68 | F36: {=IFERROR(INDEX(Data!C:C, MATCH($E36, Data!$B:$B, 0)), "")} -> 7.51 | G36: {=IFERROR(INDEX(Data!D:D, MATCH($E36, Data!$B:$B, 0)), "")} -> 11.49 | H36: {=IFERROR(INDEX(Data!E:E, MATCH($E36, Data!$B:$B, 0)), "")} -> 3.68 | I36: =INDIRECT("'"&D36&"'!M12") -> #REF! | J36: =INDIRECT("'"&D36&"'!j12") -> #REF!
A37: 35 | B37: 35 | C37: {=IFERROR(INDEX(Data!F:F, MATCH($E37, Data!$B:$B, 0)), "")} -> 21 | D37: {=IFERROR(INDEX(Data!A:A, MATCH($E37, Data!$B:$B, 0)), "")} -> 533 | E37: =LARGE(Data!$B$2:$B1000,A37 ) -> 22.41 | F37: {=IFERROR(INDEX(Data!C:C, MATCH($E37, Data!$B:$B, 0)), "")} -> 9.65 | G37: {=IFERROR(INDEX(Data!D:D, MATCH($E37, Data!$B:$B, 0)), "")} -> 6.08 | H37: {=IFERROR(INDEX(Data!E:E, MATCH($E37, Data!$B:$B, 0)), "")} -> 6.68 | I37: =INDIRECT("'"&D37&"'!M12") -> #REF! | J37: =INDIRECT("'"&D37&"'!j12") -> #REF!
A38: 36 | B38: 36 | C38: {=IFERROR(INDEX(Data!F:F, MATCH($E38, Data!$B:$B, 0)), "")} -> 38 | D38: {=IFERROR(INDEX(Data!A:A, MATCH($E38, Data!$B:$B, 0)), "")} -> 564 | E38: =LARGE(Data!$B$2:$B1000,A38 ) -> 22.11 | F38: {=IFERROR(INDEX(Data!C:C, MATCH($E38, Data!$B:$B, 0)), "")} -> 6.22 | G38: {=IFERROR(INDEX(Data!D:D, MATCH($E38, Data!$B:$B, 0)), "")} -> 9.93 | H38: {=IFERROR(INDEX(Data!E:E, MATCH($E38, Data!$B:$B, 0)), "")} -> 5.97 | I38: =INDIRECT("'"&D38&"'!M12") -> #REF! | J38: =INDIRECT("'"&D38&"'!j12") -> #REF!
A39: 37 | B39: 37 | C39: {=IFERROR(INDEX(Data!F:F, MATCH($E39, Data!$B:$B, 0)), "")} -> 41 | D39: {=IFERROR(INDEX(Data!A:A, MATCH($E39, Data!$B:$B, 0)), "")} -> 2027 | E39: =LARGE(Data!$B$2:$B1000,A39 ) -> 20.95 | F39: {=IFERROR(INDEX(Data!C:C, MATCH($E39, Data!$B:$B, 0)), "")} -> 7.32 | G39: {=IFERROR(INDEX(Data!D:D, MATCH($E39, Data!$B:$B, 0)), "")} -> 9.36 | H39: {=IFERROR(INDEX(Data!E:E, MATCH($E39, Data!$B:$B, 0)), "")} -> 4.27 | I39: =INDIRECT("'"&D39&"'!M12") -> #REF! | J39: =INDIRECT("'"&D39&"'!j12") -> #REF!
A40: 38 | B40: 38 | C40: {=IFERROR(INDEX(Data!F:F, MATCH($E40, Data!$B:$B, 0)), "")} -> 20 | D40: {=IFERROR(INDEX(Data!A:A, MATCH($E40, Data!$B:$B, 0)), "")} -> 2347 | E40: =LARGE(Data!$B$2:$B1000,A40 ) -> 20.29 | F40: {=IFERROR(INDEX(Data!C:C, MATCH($E40, Data!$B:$B, 0)), "")} -> 6.65 | G40: {=IFERROR(INDEX(Data!D:D, MATCH($E40, Data!$B:$B, 0)), "")} -> 10.59 | H40: {=IFERROR(INDEX(Data!E:E, MATCH($E40, Data!$B:$B, 0)), "")} -> 3.05 | I40: =INDIRECT("'"&D40&"'!M12") -> #REF! | J40: =INDIRECT("'"&D40&"'!j12") -> #REF!
A41: 39 | B41: 39 | C41: {=IFERROR(INDEX(Data!F:F, MATCH($E41, Data!$B:$B, 0)), "")} -> 33 | D41: {=IFERROR(INDEX(Data!A:A, MATCH($E41, Data!$B:$B, 0)), "")} -> 7673 | E41: =LARGE(Data!$B$2:$B1000,A41 ) -> 18.33 | F41: {=IFERROR(INDEX(Data!C:C, MATCH($E41, Data!$B:$B, 0)), "")} -> 4.38 | G41: {=IFERROR(INDEX(Data!D:D, MATCH($E41, Data!$B:$B, 0)), "")} -> 6.59 | H41: {=IFERROR(INDEX(Data!E:E, MATCH($E41, Data!$B:$B, 0)), "")} -> 7.36 | I41: =INDIRECT("'"&D41&"'!M12") -> #REF! | J41: =INDIRECT("'"&D41&"'!j12") -> #REF!
...

Sheet QUAL 12
D2: BLUE 1 | F2: BLUE 2 | H2: BLUE 3 | J2: RED 1 | L2: RED 2 | N2: RED 3
B4: TEAM NUMBER | D4: 7031 | F4: 7718 | H4: 1880 | J4: 250 | L4: 4121 | N4: 263 | P4: TEAM NUMBER
B6: TOTAL EPA | D6: =INDIRECT("'" & D4 & "'!C4") -> #REF! | E6: =INDIRECT("'" & E4 & "'!C4") | F6: =INDIRECT("'" & F4 & "'!C4") -> #REF! | G6: =INDIRECT("'" & G4 & "'!C4") | H6: =INDIRECT("'" & H4 & "'!C4") -> #REF! | I6: =INDIRECT("'" & I4 & "'!C4") | J6: =INDIRECT("'" & J4 & "'!C4") -> #REF! | K6: =INDIRECT("'" & K4 & "'!C4") | ... O6: =INDIRECT("'" & O4 & "'!C4") | P6: =B6 -> TOTAL EPA
P7: =B7
B8: AUTO EPA | D8: =INDIRECT("'" & D4 & "'!C6") -> #REF! | E8: =INDIRECT("'" & E4 & "'!C6") | F8: =INDIRECT("'" & F4 & "'!C6") -> #REF! | G8: =INDIRECT("'" & G4 & "'!C6") | H8: =INDIRECT("'" & H4 & "'!C6") -> #REF! | I8: =INDIRECT("'" & I4 & "'!C6") | J8: =INDIRECT("'" & J4 & "'!C6") -> #REF! | K8: =INDIRECT("'" & K4 & "'!C6") | ... O8: =INDIRECT("'" & O4 & "'!C6") | P8: =B8 -> AUTO EPA
P9: =B9
B10: TELE-OP EPA | D10: =INDIRECT("'" & D4 & "'!C8") -> #REF! | E10: =INDIRECT("'" & E4 & "'!C8") | F10: =INDIRECT("'" & F4 & "'!C8") -> #REF! | G10: =INDIRECT("'" & G4 & "'!C8") | H10: =INDIRECT("'" & H4 & "'!C8") -> #REF! | I10: =INDIRECT("'" & I4 & "'!C8") | J10: =INDIRECT("'" & J4 & "'!C8") -> #REF! | K10: =INDIRECT("'" & K4 & "'!C8") | ... O10: =INDIRECT("'" & O4 & "'!C8") | P10: =B10 -> TELE-OP EPA
P11: =B11
B12: ENDGAME EPA | D12: =INDIRECT("'" & D4 & "'!C10") -> #REF! | E12: =INDIRECT("'" & E4 & "'!C10") | F12: =INDIRECT("'" & F4 & "'!C10") -> #REF! | G12: =INDIRECT("'" & G4 & "'!C10") | H12: =INDIRECT("'" & H4 & "'!C10") -> #REF! | I12: =INDIRECT("'" & I4 & "'!C10") | J12: =INDIRECT("'" & J4 & "'!C10") -> #REF! | K12: =INDIRECT("'" & K4 & "'!C10") | ... O12: =INDIRECT("'" & O4 & "'!C10") | P12: =B12 -> ENDGAME EPA
P13: =B13
B14: TRENCH? | D14: {=INDIRECT("'" & D4 & "'!J12")} -> #REF! | F14: {=INDIRECT("'" & F4 & "'!J12")} -> #REF! | H14: {=INDIRECT("'" & H4 & "'!J12")} -> #REF! | J14: {=INDIRECT("'" & J4 & "'!J12")} -> #REF! | L14: {=INDIRECT("'" & L4 & "'!J12")} -> #REF! | N14: {=INDIRECT("'" & N4 & "'!J12")} | P14: =B14 -> TRENCH?
P15: =B15
B16: DRIVE BASE | D16: =INDIRECT("'" & D4 & "'!J5") -> #REF! | E16: =INDIRECT("'" & E4 & "'!J5") | F16: =INDIRECT("'" & F4 & "'!J5") -> #REF! | G16: =INDIRECT("'" & G4 & "'!J5") | H16: =INDIRECT("'" & H4 & "'!J5") -> #REF! | I16: =INDIRECT("'" & I4 & "'!J5") | J16: =INDIRECT("'" & J4 & "'!J5") -> #REF! | K16: =INDIRECT("'" & K4 & "'!J5") | ... O16: =INDIRECT("'" & O4 & "'!J5") | P16: =B16 -> DRIVE BASE
P17: =B17
B18: SHOOTER STYLE | D18: =INDIRECT("'" & D4 & "'!M12") -> #REF! | E18: =INDIRECT("'" & E4 & "'!M12") | F18: =INDIRECT("'" & F4 & "'!M12") -> #REF! | G18: =INDIRECT("'" & G4 & "'!M12") | H18: =INDIRECT("'" & H4 & "'!M12") -> #REF! | I18: =INDIRECT("'" & I4 & "'!M12") | J18: =INDIRECT("'" & J4 & "'!M12") -> #REF! | K18: =INDIRECT("'" & K4 & "'!M12") | ... O18: =INDIRECT("'" & O4 & "'!M12") | P18: =B18 -> SHOOTER STYLE
P19: =B19
B20: # OF LANES | D20: =INDIRECT("'" & D4 & "'!M13") -> #REF! | E20: =INDIRECT("'" & E4 & "'!M13") | F20: =INDIRECT("'" & F4 & "'!M13") -> #REF! | G20: =INDIRECT("'" & G4 & "'!M13") | H20: =INDIRECT("'" & H4 & "'!M13") -> #REF! | I20: =INDIRECT("'" & I4 & "'!M13") | J20: =INDIRECT("'" & J4 & "'!M13") -> #REF! | K20: =INDIRECT("'" & K4 & "'!M13") | ... O20: =INDIRECT("'" & O4 & "'!M13") | P20: =B20 -> # OF LANES
P21: =B21
B22: HOPPER CAPACITY | D22: =INDIRECT("'" & D4 & "'!J17") -> #REF! | E22: =INDIRECT("'" & E4 & "'!J17") | F22: =INDIRECT("'" & F4 & "'!J17") -> #REF! | G22: =INDIRECT("'" & G4 & "'!J17") | H22: =INDIRECT("'" & H4 & "'!J17") -> #REF! | J22: =INDIRECT("'" & J4 & "'!J17") -> #REF! | K22: =INDIRECT("'" & K4 & "'!J17") | L22: =INDIRECT("'" & L4 & "'!J17") -> #REF! | M22: =INDIRECT("'" & M4 & "'!J17") | N22: =INDIRECT("'" & N4 & "'!J17") | P22: =B22 -> HOPPER CAPACITY
P23: =B23
B24: SHOOT PRELOAD | D24: =INDIRECT("'" & D4 & "'!M21") -> #REF! | E24: =INDIRECT("'" & E4 & "'!M21") | F24: =INDIRECT("'" & F4 & "'!M21") -> #REF! | G24: =INDIRECT("'" & G4 & "'!M21") | H24: =INDIRECT("'" & H4 & "'!M21") -> #REF! | I24: =INDIRECT("'" & I4 & "'!M21") | J24: =INDIRECT("'" & J4 & "'!M21") -> #REF! | K24: =INDIRECT("'" & K4 & "'!M21") | ... O24: =INDIRECT("'" & O4 & "'!M21") | P24: =B24 -> SHOOT PRELOAD
P25: =B25
B26: CENTER AUTO | D26: =INDIRECT("'" & D4 & "'!M22") -> #REF! | E26: =INDIRECT("'" & E4 & "'!M22") | F26: =INDIRECT("'" & F4 & "'!M22") -> #REF! | G26: =INDIRECT("'" & G4 & "'!M22") | H26: =INDIRECT("'" & H4 & "'!M22") -> #REF! | I26: =INDIRECT("'" & I4 & "'!M22") | J26: =INDIRECT("'" & J4 & "'!M22") -> #REF! | K26: =INDIRECT("'" & K4 & "'!M22") | ... O26: =INDIRECT("'" & O4 & "'!M22") | P26: =B26 -> CENTER AUTO
P27: =B27
B28: # OF SWEEPS | D28: =INDIRECT("'" & D4 & "'!M23") -> #REF! | E28: =INDIRECT("'" & E4 & "'!M23") | F28: =INDIRECT("'" & F4 & "'!M23") -> #REF! | G28: =INDIRECT("'" & G4 & "'!M23") | H28: =INDIRECT("'" & H4 & "'!M23") -> #REF! | I28: =INDIRECT("'" & I4 & "'!M23") | J28: =INDIRECT("'" & J4 & "'!M23") -> #REF! | K28: =INDIRECT("'" & K4 & "'!M23") | ... O28: =INDIRECT("'" & O4 & "'!M23") | P28: =B28 -> # OF SWEEPS
P29: =B29
B30: DEPOT AUTO | D30: =INDIRECT("'" & D4 & "'!M24") -> #REF! | E30: =INDIRECT("'" & E4 & "'!M24") | F30: =INDIRECT("'" & F4 & "'!M24") -> #REF! | G30: =INDIRECT("'" & G4 & "'!M24") | H30: =INDIRECT("'" & H4 & "'!M24") -> #REF! | I30: =INDIRECT("'" & I4 & "'!M24") | J30: =INDIRECT("'" & J4 & "'!M24") -> #REF! | K30: =INDIRECT("'" & K4 & "'!M24") | ... O30: =INDIRECT("'" & O4 & "'!M24") | P30: =B30 -> DEPOT AUTO
P31: =B31
B32: OUTPOST AUTO | D32: =INDIRECT("'" & D4 & "'!M25") -> #REF! | E32: =INDIRECT("'" & E4 & "'!M25") | F32: =INDIRECT("'" & F4 & "'!M25") -> #REF! | G32: =INDIRECT("'" & G4 & "'!M25") | H32: =INDIRECT("'" & H4 & "'!M25") -> #REF! | I32: =INDIRECT("'" & I4 & "'!M25") | J32: =INDIRECT("'" & J4 & "'!M25") -> #REF! | K32: =INDIRECT("'" & K4 & "'!M25") | ... O32: =INDIRECT("'" & O4 & "'!M25") | P32: =B32 -> OUTPOST AUTO
P33: =B33
B34: ROBOT WEIGHT | D34: =INDIRECT("'" & D4 & "'!G5") -> #REF! | E34: =INDIRECT("'" & E4 & "'!G5") | F34: =INDIRECT("'" & F4 & "'!G5") -> #REF! | G34: =INDIRECT("'" & G4 & "'!G5") | H34: =INDIRECT("'" & H4 & "'!G5") -> #REF! | I34: =INDIRECT("'" & I4 & "'!G5") | J34: =INDIRECT("'" & J4 & "'!G5") -> #REF! | K34: =INDIRECT("'" & K4 & "'!G5") | ... O34: =INDIRECT("'" & O4 & "'!G5") | P34: =B34 -> ROBOT WEIGHT
P35: =B35
B36: TEAM NUMBER | D36: =D4 -> 7031 | E36: =E4 | F36: =F4 -> 7718 | G36: =G4 | H36: =H4 -> 1880 | I36: =I4 | J36: =J4 -> 250 | K36: =K4 | ... N36: =N4 -> 263 | P36: =B36 -> TEAM NUMBER
E38: PREDICTED SCORE | H38: =SUM(D6:H6) -> #REF! | J38: =SUM(J6:N6) -> #REF! | K38: PREDICTED SCORE

Sheet QUAL 21
D2: BLUE 1 | F2: BLUE 2 | H2: BLUE 3 | J2: RED 1 | L2: RED 2 | N2: RED 3
B4: TEAM NUMBER | D4: 10413 | F4: 5590 | H4: 1559 | J4: 263 | L4: 677 | N4: 6806 | P4: TEAM NUMBER
B6: TOTAL EPA | D6: =INDIRECT("'" & D4 & "'!C4") -> #REF! | E6: =INDIRECT("'" & E4 & "'!C4") | F6: =INDIRECT("'" & F4 & "'!C4") -> #REF! | G6: =INDIRECT("'" & G4 & "'!C4") | H6: =INDIRECT("'" & H4 & "'!C4") -> #REF! | I6: =INDIRECT("'" & I4 & "'!C4") | J6: =INDIRECT("'" & J4 & "'!C4") -> 79.71 | K6: =INDIRECT("'" & K4 & "'!C4") | ... O6: =INDIRECT("'" & O4 & "'!C4") | P6: =B6 -> TOTAL EPA
P7: =B7
B8: AUTO EPA | D8: =INDIRECT("'" & D4 & "'!C6") -> #REF! | E8: =INDIRECT("'" & E4 & "'!C6") | F8: =INDIRECT("'" & F4 & "'!C6") -> #REF! | G8: =INDIRECT("'" & G4 & "'!C6") | H8: =INDIRECT("'" & H4 & "'!C6") -> #REF! | I8: =INDIRECT("'" & I4 & "'!C6") | J8: =INDIRECT("'" & J4 & "'!C6") -> 17.33 | K8: =INDIRECT("'" & K4 & "'!C6") | ... O8: =INDIRECT("'" & O4 & "'!C6") | P8: =B8 -> AUTO EPA
P9: =B9
B10: TELE-OP EPA | D10: =INDIRECT("'" & D4 & "'!C8") -> #REF! | E10: =INDIRECT("'" & E4 & "'!C8") | F10: =INDIRECT("'" & F4 & "'!C8") -> #REF! | G10: =INDIRECT("'" & G4 & "'!C8") | H10: =INDIRECT("'" & H4 & "'!C8") -> #REF! | I10: =INDIRECT("'" & I4 & "'!C8") | J10: =INDIRECT("'" & J4 & "'!C8") -> 41.46 | K10: =INDIRECT("'" & K4 & "'!C8") | ... O10: =INDIRECT("'" & O4 & "'!C8") | P10: =B10 -> TELE-OP EPA
P11: =B11
B12: ENDGAME EPA | D12: =INDIRECT("'" & D4 & "'!C10") -> #REF! | E12: =INDIRECT("'" & E4 & "'!C10") | F12: =INDIRECT("'" & F4 & "'!C10") -> #REF! | G12: =INDIRECT("'" & G4 & "'!C10") | H12: =INDIRECT("'" & H4 & "'!C10") -> #REF! | I12: =INDIRECT("'" & I4 & "'!C10") | J12: =INDIRECT("'" & J4 & "'!C10") -> 20.92 | K12: =INDIRECT("'" & K4 & "'!C10") | ... O12: =INDIRECT("'" & O4 & "'!C10") | P12: =B12 -> ENDGAME EPA
P13: =B13
B14: TRENCH? | D14: {=INDIRECT("'" & D4 & "'!J12")} -> #REF! | F14: {=INDIRECT("'" & F4 & "'!J12")} -> #REF! | H14: {=INDIRECT("'" & H4 & "'!J12")} -> #REF! | J14: {=INDIRECT("'" & J4 & "'!J12")} | L14: {=INDIRECT("'" & L4 & "'!J12")} -> #REF! | N14: {=INDIRECT("'" & N4 & "'!J12")} -> #REF! | P14: =B14 -> TRENCH?
P15: =B15
B16: DRIVE BASE | D16: =INDIRECT("'" & D4 & "'!J5") -> #REF! | E16: =INDIRECT("'" & E4 & "'!J5") | F16: =INDIRECT("'" & F4 & "'!J5") -> #REF! | G16: =INDIRECT("'" & G4 & "'!J5") | H16: =INDIRECT("'" & H4 & "'!J5") -> #REF! | I16: =INDIRECT("'" & I4 & "'!J5") | J16: =INDIRECT("'" & J4 & "'!J5") | K16: =INDIRECT("'" & K4 & "'!J5") | ... O16: =INDIRECT("'" & O4 & "'!J5") | P16: =B16 -> DRIVE BASE
P17: =B17
B18: SHOOTER STYLE | D18: =INDIRECT("'" & D4 & "'!M12") -> #REF! | E18: =INDIRECT("'" & E4 & "'!M12") | F18: =INDIRECT("'" & F4 & "'!M12") -> #REF! | G18: =INDIRECT("'" & G4 & "'!M12") | H18: =INDIRECT("'" & H4 & "'!M12") -> #REF! | I18: =INDIRECT("'" & I4 & "'!M12") | J18: =INDIRECT("'" & J4 & "'!M12") | K18: =INDIRECT("'" & K4 & "'!M12") | ... O18: =INDIRECT("'" & O4 & "'!M12") | P18: =B18 -> SHOOTER STYLE
P19: =B19
B20: # OF LANES | D20: =INDIRECT("'" & D4 & "'!M13") -> #REF! | E20: =INDIRECT("'" & E4 & "'!M13") | F20: =INDIRECT("'" & F4 & "'!M13") -> #REF! | G20: =INDIRECT("'" & G4 & "'!M13") | H20: =INDIRECT("'" & H4 & "'!M13") -> #REF! | I20: =INDIRECT("'" & I4 & "'!M13") | J20: =INDIRECT("'" & J4 & "'!M13") | K20: =INDIRECT("'" & K4 & "'!M13") | ... O20: =INDIRECT("'" & O4 & "'!M13") | P20: =B20 -> # OF LANES
P21: =B21
B22: HOPPER CAPACITY | D22: =INDIRECT("'" & D4 & "'!J17") -> #REF! | E22: =INDIRECT("'" & E4 & "'!J17") | F22: =INDIRECT("'" & F4 & "'!J17") -> #REF! | G22: =INDIRECT("'" & G4 & "'!J17") | H22: =INDIRECT("'" & H4 & "'!J17") -> #REF! | J22: =INDIRECT("'" & J4 & "'!J17") | K22: =INDIRECT("'" & K4 & "'!J17") | L22: =INDIRECT("'" & L4 & "'!J17") -> #REF! | M22: =INDIRECT("'" & M4 & "'!J17") | N22: =INDIRECT("'" & N4 & "'!J17") -> #REF! | P22: =B22 -> HOPPER CAPACITY
P23: =B23
B24: SHOOT PRELOAD | D24: =INDIRECT("'" & D4 & "'!M21") -> #REF! | E24: =INDIRECT("'" & E4 & "'!M21") | F24: =INDIRECT("'" & F4 & "'!M21") -> #REF! | G24: =INDIRECT("'" & G4 & "'!M21") | H24: =INDIRECT("'" & H4 & "'!M21") -> #REF! | I24: =INDIRECT("'" & I4 & "'!M21") | J24: =INDIRECT("'" & J4 & "'!M21") | K24: =INDIRECT("'" & K4 & "'!M21") | ... O24: =INDIRECT("'" & O4 & "'!M21") | P24: =B24 -> SHOOT PRELOAD
P25: =B25
B26: CENTER AUTO | D26: =INDIRECT("'" & D4 & "'!M22") -> #REF! | E26: =INDIRECT("'" & E4 & "'!M22") | F26: =INDIRECT("'" & F4 & "'!M22") -> #REF! | G26: =INDIRECT("'" & G4 & "'!M22") | H26: =INDIRECT("'" & H4 & "'!M22") -> #REF! | I26: =INDIRECT("'" & I4 & "'!M22") | J26: =INDIRECT("'" & J4 & "'!M22") | K26: =INDIRECT("'" & K4 & "'!M22") | ... O26: =INDIRECT("'" & O4 & "'!M22") | P26: =B26 -> CENTER AUTO
P27: =B27
B28: # OF SWEEPS | D28: =INDIRECT("'" & D4 & "'!M23") -> #REF! | E28: =INDIRECT("'" & E4 & "'!M23") | F28: =INDIRECT("'" & F4 & "'!M23") -> #REF! | G28: =INDIRECT("'" & G4 & "'!M23") | H28: =INDIRECT("'" & H4 & "'!M23") -> #REF! | I28: =INDIRECT("'" & I4 & "'!M23") | J28: =INDIRECT("'" & J4 & "'!M23") | K28: =INDIRECT("'" & K4 & "'!M23") | ... O28: =INDIRECT("'" & O4 & "'!M23") | P28: =B28 -> # OF SWEEPS
P29: =B29
B30: DEPOT AUTO | D30: =INDIRECT("'" & D4 & "'!M24") -> #REF! | E30: =INDIRECT("'" & E4 & "'!M24") | F30: =INDIRECT("'" & F4 & "'!M24") -> #REF! | G30: =INDIRECT("'" & G4 & "'!M24") | H30: =INDIRECT("'" & H4 & "'!M24") -> #REF! | I30: =INDIRECT("'" & I4 & "'!M24") | J30: =INDIRECT("'" & J4 & "'!M24") | K30: =INDIRECT("'" & K4 & "'!M24") | ... O30: =INDIRECT("'" & O4 & "'!M24") | P30: =B30 -> DEPOT AUTO
P31: =B31
B32: OUTPOST AUTO | D32: =INDIRECT("'" & D4 & "'!M25") -> #REF! | E32: =INDIRECT("'" & E4 & "'!M25") | F32: =INDIRECT("'" & F4 & "'!M25") -> #REF! | G32: =INDIRECT("'" & G4 & "'!M25") | H32: =INDIRECT("'" & H4 & "'!M25") -> #REF! | I32: =INDIRECT("'" & I4 & "'!M25") | J32: =INDIRECT("'" & J4 & "'!M25") | K32: =INDIRECT("'" & K4 & "'!M25") | ... O32: =INDIRECT("'" & O4 & "'!M25") | P32: =B32 -> OUTPOST AUTO
P33: =B33
B34: ROBOT WEIGHT | D34: =INDIRECT("'" & D4 & "'!G5") -> #REF! | E34: =INDIRECT("'" & E4 & "'!G5") | F34: =INDIRECT("'" & F4 & "'!G5") -> #REF! | G34: =INDIRECT("'" & G4 & "'!G5") | H34: =INDIRECT("'" & H4 & "'!G5") -> #REF! | I34: =INDIRECT("'" & I4 & "'!G5") | J34: =INDIRECT("'" & J4 & "'!G5") -> SWERVE | K34: =INDIRECT("'" & K4 & "'!G5") | ... O34: =INDIRECT("'" & O4 & "'!G5") | P34: =B34 -> ROBOT WEIGHT
P35: =B35
B36: TEAM NUMBER | D36: =D4 -> 10413 | E36: =E4 | F36: =F4 -> 5590 | G36: =G4 | H36: =H4 -> 1559 | I36: =I4 | J36: =J4 -> 263 | K36: =K4 | ... N36: =N4 -> 6806 | P36: =B36 -> TEAM NUMBER
E38: PREDICTED SCORE | H38: =SUM(D6:H6) -> #REF! | J38: =SUM(J6:N6) -> #REF! | K38: PREDICTED SCORE

Sheet QUAL 32
D2: BLUE 1 | F2: BLUE 2 | H2: BLUE 3 | J2: RED 1 | L2: RED 2 | N2: RED 3
B4: TEAM NUMBER | D4: 3003 | F4: 7605 | H4: 1796 | J4: 5149 | L4: 533 | N4: 263 | P4: TEAM NUMBER
B6: TOTAL EPA | D6: =INDIRECT("'" & D4 & "'!C4") -> #REF! | E6: =INDIRECT("'" & E4 & "'!C4") | F6: =INDIRECT("'" & F4 & "'!C4") -> #REF! | G6: =INDIRECT("'" & G4 & "'!C4") | H6: =INDIRECT("'" & H4 & "'!C4") -> #REF! | I6: =INDIRECT("'" & I4 & "'!C4") | J6: =INDIRECT("'" & J4 & "'!C4") -> #REF! | K6: =INDIRECT("'" & K4 & "'!C4") | ... O6: =INDIRECT("'" & O4 & "'!C4") | P6: =B6 -> TOTAL EPA
P7: =B7
B8: AUTO EPA | D8: =INDIRECT("'" & D4 & "'!C6") -> #REF! | E8: =INDIRECT("'" & E4 & "'!C6") | F8: =INDIRECT("'" & F4 & "'!C6") -> #REF! | G8: =INDIRECT("'" & G4 & "'!C6") | H8: =INDIRECT("'" & H4 & "'!C6") -> #REF! | I8: =INDIRECT("'" & I4 & "'!C6") | J8: =INDIRECT("'" & J4 & "'!C6") -> #REF! | K8: =INDIRECT("'" & K4 & "'!C6") | ... O8: =INDIRECT("'" & O4 & "'!C6") | P8: =B8 -> AUTO EPA
P9: =B9
B10: TELE-OP EPA | D10: =INDIRECT("'" & D4 & "'!C8") -> #REF! | E10: =INDIRECT("'" & E4 & "'!C8") | F10: =INDIRECT("'" & F4 & "'!C8") -> #REF! | G10: =INDIRECT("'" & G4 & "'!C8") | H10: =INDIRECT("'" & H4 & "'!C8") -> #REF! | I10: =INDIRECT("'" & I4 & "'!C8") | J10: =INDIRECT("'" & J4 & "'!C8") -> #REF! | K10: =INDIRECT("'" & K4 & "'!C8") | ... O10: =INDIRECT("'" & O4 & "'!C8") | P10: =B10 -> TELE-OP EPA
P11: =B11
B12: ENDGAME EPA | D12: =INDIRECT("'" & D4 & "'!C10") -> #REF! | E12: =INDIRECT("'" & E4 & "'!C10") | F12: =INDIRECT("'" & F4 & "'!C10") -> #REF! | G12: =INDIRECT("'" & G4 & "'!C10") | H12: =INDIRECT("'" & H4 & "'!C10") -> #REF! | I12: =INDIRECT("'" & I4 & "'!C10") | J12: =INDIRECT("'" & J4 & "'!C10") -> #REF! | K12: =INDIRECT("'" & K4 & "'!C10") | ... O12: =INDIRECT("'" & O4 & "'!C10") | P12: =B12 -> ENDGAME EPA
P13: =B13
B14: TRENCH? | D14: {=INDIRECT("'" & D4 & "'!J12")} -> #REF! | F14: {=INDIRECT("'" & F4 & "'!J12")} -> #REF! | H14: {=INDIRECT("'" & H4 & "'!J12")} -> #REF! | J14: {=INDIRECT("'" & J4 & "'!J12")} -> #REF! | L14: {=INDIRECT("'" & L4 & "'!J12")} -> #REF! | N14: {=INDIRECT("'" & N4 & "'!J12")} | P14: =B14 -> TRENCH?
P15: =B15
B16: DRIVE BASE | D16: =INDIRECT("'" & D4 & "'!J5") -> #REF! | E16: =INDIRECT("'" & E4 & "'!J5") | F16: =INDIRECT("'" & F4 & "'!J5") -> #REF! | G16: =INDIRECT("'" & G4 & "'!J5") | H16: =INDIRECT("'" & H4 & "'!J5") -> #REF! | I16: =INDIRECT("'" & I4 & "'!J5") | J16: =INDIRECT("'" & J4 & "'!J5") -> #REF! | K16: =INDIRECT("'" & K4 & "'!J5") | ... O16: =INDIRECT("'" & O4 & "'!J5") | P16: =B16 -> DRIVE BASE
P17: =B17
B18: SHOOTER STYLE | D18: =INDIRECT("'" & D4 & "'!M12") -> #REF! | E18: =INDIRECT("'" & E4 & "'!M12") | F18: =INDIRECT("'" & F4 & "'!M12") -> #REF! | G18: =INDIRECT("'" & G4 & "'!M12") | H18: =INDIRECT("'" & H4 & "'!M12") -> #REF! | I18: =INDIRECT("'" & I4 & "'!M12") | J18: =INDIRECT("'" & J4 & "'!M12") -> #REF! | K18: =INDIRECT("'" & K4 & "'!M12") | ... O18: =INDIRECT("'" & O4 & "'!M12") | P18: =B18 -> SHOOTER STYLE
P19: =B19
B20: # OF LANES | D20: =INDIRECT("'" & D4 & "'!M13") -> #REF! | E20: =INDIRECT("'" & E4 & "'!M13") | F20: =INDIRECT("'" & F4 & "'!M13") -> #REF! | G20: =INDIRECT("'" & G4 & "'!M13") | H20: =INDIRECT("'" & H4 & "'!M13") -> #REF! | I20: =INDIRECT("'" & I4 & "'!M13") | J20: =INDIRECT("'" & J4 & "'!M13") -> #REF! | K20: =INDIRECT("'" & K4 & "'!M13") | ... O20: =INDIRECT("'" & O4 & "'!M13") | P20: =B20 -> # OF LANES
P21: =B21
B22: HOPPER CAPACITY | D22: =INDIRECT("'" & D4 & "'!J17") -> #REF! | E22: =INDIRECT("'" & E4 & "'!J17") | F22: =INDIRECT("'" & F4 & "'!J17") -> #REF! | G22: =INDIRECT("'" & G4 & "'!J17") | H22: =INDIRECT("'" & H4 & "'!J17") -> #REF! | J22: =INDIRECT("'" & J4 & "'!J17") -> #REF! | K22: =INDIRECT("'" & K4 & "'!J17") | L22: =INDIRECT("'" & L4 & "'!J17") -> #REF! | M22: =INDIRECT("'" & M4 & "'!J17") | N22: =INDIRECT("'" & N4 & "'!J17") | P22: =B22 -> HOPPER CAPACITY
P23: =B23
B24: SHOOT PRELOAD | D24: =INDIRECT("'" & D4 & "'!M21") -> #REF! | E24: =INDIRECT("'" & E4 & "'!M21") | F24: =INDIRECT("'" & F4 & "'!M21") -> #REF! | G24: =INDIRECT("'" & G4 & "'!M21") | H24: =INDIRECT("'" & H4 & "'!M21") -> #REF! | I24: =INDIRECT("'" & I4 & "'!M21") | J24: =INDIRECT("'" & J4 & "'!M21") -> #REF! | K24: =INDIRECT("'" & K4 & "'!M21") | ... O24: =INDIRECT("'" & O4 & "'!M21") | P24: =B24 -> SHOOT PRELOAD
P25: =B25
B26: CENTER AUTO | D26: =INDIRECT("'" & D4 & "'!M22") -> #REF! | E26: =INDIRECT("'" & E4 & "'!M22") | F26: =INDIRECT("'" & F4 & "'!M22") -> #REF! | G26: =INDIRECT("'" & G4 & "'!M22") | H26: =INDIRECT("'" & H4 & "'!M22") -> #REF! | I26: =INDIRECT("'" & I4 & "'!M22") | J26: =INDIRECT("'" & J4 & "'!M22") -> #REF! | K26: =INDIRECT("'" & K4 & "'!M22") | ... O26: =INDIRECT("'" & O4 & "'!M22") | P26: =B26 -> CENTER AUTO
P27: =B27
B28: # OF SWEEPS | D28: =INDIRECT("'" & D4 & "'!M23") -> #REF! | E28: =INDIRECT("'" & E4 & "'!M23") | F28: =INDIRECT("'" & F4 & "'!M23") -> #REF! | G28: =INDIRECT("'" & G4 & "'!M23") | H28: =INDIRECT("'" & H4 & "'!M23") -> #REF! | I28: =INDIRECT("'" & I4 & "'!M23") | J28: =INDIRECT("'" & J4 & "'!M23") -> #REF! | K28: =INDIRECT("'" & K4 & "'!M23") | ... O28: =INDIRECT("'" & O4 & "'!M23") | P28: =B28 -> # OF SWEEPS
P29: =B29
B30: DEPOT AUTO | D30: =INDIRECT("'" & D4 & "'!M24") -> #REF! | E30: =INDIRECT("'" & E4 & "'!M24") | F30: =INDIRECT("'" & F4 & "'!M24") -> #REF! | G30: =INDIRECT("'" & G4 & "'!M24") | H30: =INDIRECT("'" & H4 & "'!M24") -> #REF! | I30: =INDIRECT("'" & I4 & "'!M24") | J30: =INDIRECT("'" & J4 & "'!M24") -> #REF! | K30: =INDIRECT("'" & K4 & "'!M24") | ... O30: =INDIRECT("'" & O4 & "'!M24") | P30: =B30 -> DEPOT AUTO
P31: =B31
B32: OUTPOST AUTO | D32: =INDIRECT("'" & D4 & "'!M25") -> #REF! | E32: =INDIRECT("'" & E4 & "'!M25") | F32: =INDIRECT("'" & F4 & "'!M25") -> #REF! | G32: =INDIRECT("'" & G4 & "'!M25") | H32: =INDIRECT("'" & H4 & "'!M25") -> #REF! | I32: =INDIRECT("'" & I4 & "'!M25") | J32: =INDIRECT("'" & J4 & "'!M25") -> #REF! | K32: =INDIRECT("'" & K4 & "'!M25") | ... O32: =INDIRECT("'" & O4 & "'!M25") | P32: =B32 -> OUTPOST AUTO
P33: =B33
B34: ROBOT WEIGHT | D34: =INDIRECT("'" & D4 & "'!G5") -> #REF! | E34: =INDIRECT("'" & E4 & "'!G5") | F34: =INDIRECT("'" & F4 & "'!G5") -> #REF! | G34: =INDIRECT("'" & G4 & "'!G5") | H34: =INDIRECT("'" & H4 & "'!G5") -> #REF! | I34: =INDIRECT("'" & I4 & "'!G5") | J34: =INDIRECT("'" & J4 & "'!G5") -> #REF! | K34: =INDIRECT("'" & K4 & "'!G5") | ... O34: =INDIRECT("'" & O4 & "'!G5") | P34: =B34 -> ROBOT WEIGHT
P35: =B35
B36: TEAM NUMBER | D36: =D4 -> 3003 | E36: =E4 | F36: =F4 -> 7605 | G36: =G4 | H36: =H4 -> 1796 | I36: =I4 | J36: =J4 -> 5149 | K36: =K4 | ... N36: =N4 -> 263 | P36: =B36 -> TEAM NUMBER
E38: PREDICTED SCORE | H38: =SUM(D6:H6) -> #REF! | J38: =SUM(J6:N6) -> #REF! | K38: PREDICTED SCORE

Sheet QUAL 41
D2: BLUE 1 | F2: BLUE 2 | H2: BLUE 3 | J2: RED 1 | L2: RED 2 | N2: RED 3
B4: TEAM NUMBER | D4: 263 | F4: 10413 | H4: 1493 | J4: 578 | L4: 9194 | N4: 4930 | P4: TEAM NUMBER
B6: TOTAL EPA | D6: =INDIRECT("'" & D4 & "'!C4") -> 79.71 | E6: =INDIRECT("'" & E4 & "'!C4") | F6: =INDIRECT("'" & F4 & "'!C4") -> #REF! | G6: =INDIRECT("'" & G4 & "'!C4") | H6: =INDIRECT("'" & H4 & "'!C4") -> #REF! | I6: =INDIRECT("'" & I4 & "'!C4") | J6: =INDIRECT("'" & J4 & "'!C4") -> #REF! | K6: =INDIRECT("'" & K4 & "'!C4") | ... O6: =INDIRECT("'" & O4 & "'!C4") | P6: =B6 -> TOTAL EPA
P7: =B7
B8: AUTO EPA | D8: =INDIRECT("'" & D4 & "'!C6") -> 17.33 | E8: =INDIRECT("'" & E4 & "'!C6") | F8: =INDIRECT("'" & F4 & "'!C6") -> #REF! | G8: =INDIRECT("'" & G4 & "'!C6") | H8: =INDIRECT("'" & H4 & "'!C6") -> #REF! | I8: =INDIRECT("'" & I4 & "'!C6") | J8: =INDIRECT("'" & J4 & "'!C6") -> #REF! | K8: =INDIRECT("'" & K4 & "'!C6") | ... O8: =INDIRECT("'" & O4 & "'!C6") | P8: =B8 -> AUTO EPA
P9: =B9
B10: TELE-OP EPA | D10: =INDIRECT("'" & D4 & "'!C8") -> 41.46 | E10: =INDIRECT("'" & E4 & "'!C8") | F10: =INDIRECT("'" & F4 & "'!C8") -> #REF! | G10: =INDIRECT("'" & G4 & "'!C8") | H10: =INDIRECT("'" & H4 & "'!C8") -> #REF! | I10: =INDIRECT("'" & I4 & "'!C8") | J10: =INDIRECT("'" & J4 & "'!C8") -> #REF! | K10: =INDIRECT("'" & K4 & "'!C8") | ... O10: =INDIRECT("'" & O4 & "'!C8") | P10: =B10 -> TELE-OP EPA
P11: =B11
B12: ENDGAME EPA | D12: =INDIRECT("'" & D4 & "'!C10") -> 20.92 | E12: =INDIRECT("'" & E4 & "'!C10") | F12: =INDIRECT("'" & F4 & "'!C10") -> #REF! | G12: =INDIRECT("'" & G4 & "'!C10") | H12: =INDIRECT("'" & H4 & "'!C10") -> #REF! | I12: =INDIRECT("'" & I4 & "'!C10") | J12: =INDIRECT("'" & J4 & "'!C10") -> #REF! | K12: =INDIRECT("'" & K4 & "'!C10") | ... O12: =INDIRECT("'" & O4 & "'!C10") | P12: =B12 -> ENDGAME EPA
P13: =B13
B14: TRENCH? | D14: {=INDIRECT("'" & D4 & "'!J12")} | F14: {=INDIRECT("'" & F4 & "'!J12")} -> #REF! | H14: {=INDIRECT("'" & H4 & "'!J12")} -> #REF! | J14: {=INDIRECT("'" & J4 & "'!J12")} -> #REF! | L14: {=INDIRECT("'" & L4 & "'!J12")} -> #REF! | N14: {=INDIRECT("'" & N4 & "'!J12")} -> #REF! | P14: =B14 -> TRENCH?
P15: =B15
B16: DRIVE BASE | D16: =INDIRECT("'" & D4 & "'!J5") | E16: =INDIRECT("'" & E4 & "'!J5") | F16: =INDIRECT("'" & F4 & "'!J5") -> #REF! | G16: =INDIRECT("'" & G4 & "'!J5") | H16: =INDIRECT("'" & H4 & "'!J5") -> #REF! | I16: =INDIRECT("'" & I4 & "'!J5") | J16: =INDIRECT("'" & J4 & "'!J5") -> #REF! | K16: =INDIRECT("'" & K4 & "'!J5") | ... O16: =INDIRECT("'" & O4 & "'!J5") | P16: =B16 -> DRIVE BASE
P17: =B17
B18: SHOOTER STYLE | D18: =INDIRECT("'" & D4 & "'!M12") | E18: =INDIRECT("'" & E4 & "'!M12") | F18: =INDIRECT("'" & F4 & "'!M12") -> #REF! | G18: =INDIRECT("'" & G4 & "'!M12") | H18: =INDIRECT("'" & H4 & "'!M12") -> #REF! | I18: =INDIRECT("'" & I4 & "'!M12") | J18: =INDIRECT("'" & J4 & "'!M12") -> #REF! | K18: =INDIRECT("'" & K4 & "'!M12") | ... O18: =INDIRECT("'" & O4 & "'!M12") | P18: =B18 -> SHOOTER STYLE
P19: =B19
B20: # OF LANES | D20: =INDIRECT("'" & D4 & "'!M13") | E20: =INDIRECT("'" & E4 & "'!M13") | F20: =INDIRECT("'" & F4 & "'!M13") -> #REF! | G20: =INDIRECT("'" & G4 & "'!M13") | H20: =INDIRECT("'" & H4 & "'!M13") -> #REF! | I20: =INDIRECT("'" & I4 & "'!M13") | J20: =INDIRECT("'" & J4 & "'!M13") -> #REF! | K20: =INDIRECT("'" & K4 & "'!M13") | ... O20: =INDIRECT("'" & O4 & "'!M13") | P20: =B20 -> # OF LANES
P21: =B21
B22: HOPPER CAPACITY | D22: =INDIRECT("'" & D4 & "'!J17") | E22: =INDIRECT("'" & E4 & "'!J17") | F22: =INDIRECT("'" & F4 & "'!J17") -> #REF! | G22: =INDIRECT("'" & G4 & "'!J17") | H22: =INDIRECT("'" & H4 & "'!J17") -> #REF! | J22: =INDIRECT("'" & J4 & "'!J17") -> #REF! | K22: =INDIRECT("'" & K4 & "'!J17") | L22: =INDIRECT("'" & L4 & "'!J17") -> #REF! | M22: =INDIRECT("'" & M4 & "'!J17") | N22: =INDIRECT("'" & N4 & "'!J17") -> #REF! | P22: =B22 -> HOPPER CAPACITY
P23: =B23
B24: SHOOT PRELOAD | D24: =INDIRECT("'" & D4 & "'!M21") | E24: =INDIRECT("'" & E4 & "'!M21") | F24: =INDIRECT("'" & F4 & "'!M21") -> #REF! | G24: =INDIRECT("'" & G4 & "'!M21") | H24: =INDIRECT("'" & H4 & "'!M21") -> #REF! | I24: =INDIRECT("'" & I4 & "'!M21") | J24: =INDIRECT("'" & J4 & "'!M21") -> #REF! | K24: =INDIRECT("'" & K4 & "'!M21") | ... O24: =INDIRECT("'" & O4 & "'!M21") | P24: =B24 -> SHOOT PRELOAD
P25: =B25
B26: CENTER AUTO | D26: =INDIRECT("'" & D4 & "'!M22") | E26: =INDIRECT("'" & E4 & "'!M22") | F26: =INDIRECT("'" & F4 & "'!M22") -> #REF! | G26: =INDIRECT("'" & G4 & "'!M22") | H26: =INDIRECT("'" & H4 & "'!M22") -> #REF! | I26: =INDIRECT("'" & I4 & "'!M22") | J26: =INDIRECT("'" & J4 & "'!M22") -> #REF! | K26: =INDIRECT("'" & K4 & "'!M22") | ... O26: =INDIRECT("'" & O4 & "'!M22") | P26: =B26 -> CENTER AUTO
P27: =B27
B28: # OF SWEEPS | D28: =INDIRECT("'" & D4 & "'!M23") | E28: =INDIRECT("'" & E4 & "'!M23") | F28: =INDIRECT("'" & F4 & "'!M23") -> #REF! | G28: =INDIRECT("'" & G4 & "'!M23") | H28: =INDIRECT("'" & H4 & "'!M23") -> #REF! | I28: =INDIRECT("'" & I4 & "'!M23") | J28: =INDIRECT("'" & J4 & "'!M23") -> #REF! | K28: =INDIRECT("'" & K4 & "'!M23") | ... O28: =INDIRECT("'" & O4 & "'!M23") | P28: =B28 -> # OF SWEEPS
P29: =B29
B30: DEPOT AUTO | D30: =INDIRECT("'" & D4 & "'!M24") | E30: =INDIRECT("'" & E4 & "'!M24") | F30: =INDIRECT("'" & F4 & "'!M24") -> #REF! | G30: =INDIRECT("'" & G4 & "'!M24") | H30: =INDIRECT("'" & H4 & "'!M24") -> #REF! | I30: =INDIRECT("'" & I4 & "'!M24") | J30: =INDIRECT("'" & J4 & "'!M24") -> #REF! | K30: =INDIRECT("'" & K4 & "'!M24") | ... O30: =INDIRECT("'" & O4 & "'!M24") | P30: =B30 -> DEPOT AUTO
P31: =B31
B32: OUTPOST AUTO | D32: =INDIRECT("'" & D4 & "'!M25") | E32: =INDIRECT("'" & E4 & "'!M25") | F32: =INDIRECT("'" & F4 & "'!M25") -> #REF! | G32: =INDIRECT("'" & G4 & "'!M25") | H32: =INDIRECT("'" & H4 & "'!M25") -> #REF! | I32: =INDIRECT("'" & I4 & "'!M25") | J32: =INDIRECT("'" & J4 & "'!M25") -> #REF! | K32: =INDIRECT("'" & K4 & "'!M25") | ... O32: =INDIRECT("'" & O4 & "'!M25") | P32: =B32 -> OUTPOST AUTO
P33: =B33
B34: ROBOT WEIGHT | D34: =INDIRECT("'" & D4 & "'!G5") -> SWERVE | E34: =INDIRECT("'" & E4 & "'!G5") | F34: =INDIRECT("'" & F4 & "'!G5") -> #REF! | G34: =INDIRECT("'" & G4 & "'!G5") | H34: =INDIRECT("'" & H4 & "'!G5") -> #REF! | I34: =INDIRECT("'" & I4 & "'!G5") | J34: =INDIRECT("'" & J4 & "'!G5") -> #REF! | K34: =INDIRECT("'" & K4 & "'!G5") | ... O34: =INDIRECT("'" & O4 & "'!G5") | P34: =B34 -> ROBOT WEIGHT
P35: =B35
B36: TEAM NUMBER | D36: =D4 -> 263 | E36: =E4 | F36: =F4 -> 10413 | G36: =G4 | H36: =H4 -> 1493 | I36: =I4 | J36: =J4 -> 578 | K36: =K4 | ... N36: =N4 -> 4930 | P36: =B36 -> TEAM NUMBER
E38: PREDICTED SCORE | H38: =SUM(D6:H6) -> #REF! | J38: =SUM(J6:N6) -> #REF! | K38: PREDICTED SCORE

Sheet QUAL 51
D2: BLUE 1 | F2: BLUE 2 | H2: BLUE 3 | J2: RED 1 | L2: RED 2 | N2: RED 3
B4: TEAM NUMBER | D4: 5881 | F4: 263 | H4: 1591 | J4: 870 | L4: 4122 | N4: 3044 | P4: TEAM NUMBER
B6: TOTAL EPA | D6: =INDIRECT("'" & D4 & "'!C4") -> #REF! | E6: =INDIRECT("'" & E4 & "'!C4") | F6: =INDIRECT("'" & F4 & "'!C4") -> 79.71 | G6: =INDIRECT("'" & G4 & "'!C4") | H6: =INDIRECT("'" & H4 & "'!C4") -> #REF! | I6: =INDIRECT("'" & I4 & "'!C4") | J6: =INDIRECT("'" & J4 & "'!C4") -> #REF! | K6: =INDIRECT("'" & K4 & "'!C4") | ... O6: =INDIRECT("'" & O4 & "'!C4") | P6: =B6 -> TOTAL EPA
P7: =B7
B8: AUTO EPA | D8: =INDIRECT("'" & D4 & "'!C6") -> #REF! | E8: =INDIRECT("'" & E4 & "'!C6") | F8: =INDIRECT("'" & F4 & "'!C6") -> 17.33 | G8: =INDIRECT("'" & G4 & "'!C6") | H8: =INDIRECT("'" & H4 & "'!C6") -> #REF! | I8: =INDIRECT("'" & I4 & "'!C6") | J8: =INDIRECT("'" & J4 & "'!C6") -> #REF! | K8: =INDIRECT("'" & K4 & "'!C6") | ... O8: =INDIRECT("'" & O4 & "'!C6") | P8: =B8 -> AUTO EPA
P9: =B9
B10: TELE-OP EPA | D10: =INDIRECT("'" & D4 & "'!C8") -> #REF! | E10: =INDIRECT("'" & E4 & "'!C8") | F10: =INDIRECT("'" & F4 & "'!C8") -> 41.46 | G10: =INDIRECT("'" & G4 & "'!C8") | H10: =INDIRECT("'" & H4 & "'!C8") -> #REF! | I10: =INDIRECT("'" & I4 & "'!C8") | J10: =INDIRECT("'" & J4 & "'!C8") -> #REF! | K10: =INDIRECT("'" & K4 & "'!C8") | ... O10: =INDIRECT("'" & O4 & "'!C8") | P10: =B10 -> TELE-OP EPA
P11: =B11
B12: ENDGAME EPA | D12: =INDIRECT("'" & D4 & "'!C10") -> #REF! | E12: =INDIRECT("'" & E4 & "'!C10") | F12: =INDIRECT("'" & F4 & "'!C10") -> 20.92 | G12: =INDIRECT("'" & G4 & "'!C10") | H12: =INDIRECT("'" & H4 & "'!C10") -> #REF! | I12: =INDIRECT("'" & I4 & "'!C10") | J12: =INDIRECT("'" & J4 & "'!C10") -> #REF! | K12: =INDIRECT("'" & K4 & "'!C10") | ... O12: =INDIRECT("'" & O4 & "'!C10") | P12: =B12 -> ENDGAME EPA
P13: =B13
B14: TRENCH? | D14: {=INDIRECT("'" & D4 & "'!J12")} -> #REF! | F14: {=INDIRECT("'" & F4 & "'!J12")} | H14: {=INDIRECT("'" & H4 & "'!J12")} -> #REF! | J14: {=INDIRECT("'" & J4 & "'!J12")} -> #REF! | L14: {=INDIRECT("'" & L4 & "'!J12")} -> #REF! | N14: {=INDIRECT("'" & N4 & "'!J12")} -> #REF! | P14: =B14 -> TRENCH?
P15: =B15
B16: DRIVE BASE | D16: =INDIRECT("'" & D4 & "'!J5") -> #REF! | E16: =INDIRECT("'" & E4 & "'!J5") | F16: =INDIRECT("'" & F4 & "'!J5") | G16: =INDIRECT("'" & G4 & "'!J5") | H16: =INDIRECT("'" & H4 & "'!J5") -> #REF! | I16: =INDIRECT("'" & I4 & "'!J5") | J16: =INDIRECT("'" & J4 & "'!J5") -> #REF! | K16: =INDIRECT("'" & K4 & "'!J5") | ... O16: =INDIRECT("'" & O4 & "'!J5") | P16: =B16 -> DRIVE BASE
P17: =B17
B18: SHOOTER STYLE | D18: =INDIRECT("'" & D4 & "'!M12") -> #REF! | E18: =INDIRECT("'" & E4 & "'!M12") | F18: =INDIRECT("'" & F4 & "'!M12") | G18: =INDIRECT("'" & G4 & "'!M12") | H18: =INDIRECT("'" & H4 & "'!M12") -> #REF! | I18: =INDIRECT("'" & I4 & "'!M12") | J18: =INDIRECT("'" & J4 & "'!M12") -> #REF! | K18: =INDIRECT("'" & K4 & "'!M12") | ... O18: =INDIRECT("'" & O4 & "'!M12") | P18: =B18 -> SHOOTER STYLE
P19: =B19
B20: # OF LANES | D20: =INDIRECT("'" & D4 & "'!M13") -> #REF! | E20: =INDIRECT("'" & E4 & "'!M13") | F20: =INDIRECT("'" & F4 & "'!M13") | G20: =INDIRECT("'" & G4 & "'!M13") | H20: =INDIRECT("'" & H4 & "'!M13") -> #REF! | I20: =INDIRECT("'" & I4 & "'!M13") | J20: =INDIRECT("'" & J4 & "'!M13") -> #REF! | K20: =INDIRECT("'" & K4 & "'!M13") | ... O20: =INDIRECT("'" & O4 & "'!M13") | P20: =B20 -> # OF LANES
P21: =B21
B22: HOPPER CAPACITY | D22: =INDIRECT("'" & D4 & "'!J17") -> #REF! | E22: =INDIRECT("'" & E4 & "'!J17") | F22: =INDIRECT("'" & F4 & "'!J17") | G22: =INDIRECT("'" & G4 & "'!J17") | H22: =INDIRECT("'" & H4 & "'!J17") -> #REF! | J22: =INDIRECT("'" & J4 & "'!J17") -> #REF! | K22: =INDIRECT("'" & K4 & "'!J17") | L22: =INDIRECT("'" & L4 & "'!J17") -> #REF! | M22: =INDIRECT("'" & M4 & "'!J17") | N22: =INDIRECT("'" & N4 & "'!J17") -> #REF! | P22: =B22 -> HOPPER CAPACITY
P23: =B23
B24: SHOOT PRELOAD | D24: =INDIRECT("'" & D4 & "'!M21") -> #REF! | E24: =INDIRECT("'" & E4 & "'!M21") | F24: =INDIRECT("'" & F4 & "'!M21") | G24: =INDIRECT("'" & G4 & "'!M21") | H24: =INDIRECT("'" & H4 & "'!M21") -> #REF! | I24: =INDIRECT("'" & I4 & "'!M21") | J24: =INDIRECT("'" & J4 & "'!M21") -> #REF! | K24: =INDIRECT("'" & K4 & "'!M21") | ... O24: =INDIRECT("'" & O4 & "'!M21") | P24: =B24 -> SHOOT PRELOAD
P25: =B25
B26: CENTER AUTO | D26: =INDIRECT("'" & D4 & "'!M22") -> #REF! | E26: =INDIRECT("'" & E4 & "'!M22") | F26: =INDIRECT("'" & F4 & "'!M22") | G26: =INDIRECT("'" & G4 & "'!M22") | H26: =INDIRECT("'" & H4 & "'!M22") -> #REF! | I26: =INDIRECT("'" & I4 & "'!M22") | J26: =INDIRECT("'" & J4 & "'!M22") -> #REF! | K26: =INDIRECT("'" & K4 & "'!M22") | ... O26: =INDIRECT("'" & O4 & "'!M22") | P26: =B26 -> CENTER AUTO
P27: =B27
B28: # OF SWEEPS | D28: =INDIRECT("'" & D4 & "'!M23") -> #REF! | E28: =INDIRECT("'" & E4 & "'!M23") | F28: =INDIRECT("'" & F4 & "'!M23") | G28: =INDIRECT("'" & G4 & "'!M23") | H28: =INDIRECT("'" & H4 & "'!M23") -> #REF! | I28: =INDIRECT("'" & I4 & "'!M23") | J28: =INDIRECT("'" & J4 & "'!M23") -> #REF! | K28: =INDIRECT("'" & K4 & "'!M23") | ... O28: =INDIRECT("'" & O4 & "'!M23") | P28: =B28 -> # OF SWEEPS
P29: =B29
